Workbook

Sheet Final Sample
A1: S/N | B1: Firm_ID | C1: Ticker | D1: Company Name | E1: Sector | F1: Year | G1: Voluntary_Adoption_Period | H1: IFRS_S1S2_Adopter_Dummy | I1: SDQ_Score (0-100) | J1: CDQ_Score (0-100) | K1: Shares_Outstanding | L1: Share_Price_YearEnd (NGN) | M1: Market_Value_Equity (NGN'000) | N1: Total_Liabilities (NGN'000) | O1: Total_Assets (NGN'000) | P1: Net_Income (NGN'000) | Q1: Tobin_Q | R1: Firm_Size (LN Total Assets) | S1: Leverage | T1: ROA | U1: Year_Incorporation | V1: Firm_Age | W1: Big4_Auditor (1/0) | X1: Auditor_Name | Y1: Notes / Data Quality Flags | Z1: NGX_Compliance_Status (CSI) | AA1: Tobin_Q_Wins (0.5/99.5 pct) | AB1: Leverage_Wins (0.5/99.5 pct) | AC1: ROA_Wins (0.5/99.5 pct)
A2: 1 | B2: 1 | C2: ABBEYBANK | D2: Abbey Mortgage Bank Plc | E2: FINANCIAL SERVICES | F2: 2021 | G2: 0 | H2: 0 | I2: 5 | J2: 0 | K2: 10153846154 | L2: 0.6618 | M2: 6719815.4 | N2: 27528179 | O2: 34460435 | P2: 622198 | Q2: 0.99383523 | R2: 17.355322 | S2: 0.79883434 | T2: 0.018055431 | U2: 1991 | V2: 30 | W2: 1 | X2: PricewaterhouseCoopers | Y2: Market cap Dec-31-2021 ~6.72B NGN. Share_Price_YearEnd = Dec-31 market cap / Shares_Outstanding, market cap from S&P Global Market Intelligence (via stockanalysis.com). MEDIUM-HIGH confidence (billions-precision source rounding). | IFRS_S1S2_Adopter_Dummy=0, Board_Independence=11.11% (1 Independent NED of 9 total board members, explicitly stated in FY2021 Corporate Governance Report), Ownership_Concentration=39.6% (largest single substantial shareholder, VFD Group Plc, per FY2021 Report of the Directors substantial-interest table). Full SDQ/CDQ disclosure coding completed this pass -- see Coding Sheet. | Z2: ok | AA2: =MIN(MAX(Q2,PERCENTILE(Q$2:Q$612,0.005)),PERCENTILE(Q$2:Q$612,0.995)) -> 0.99383523 | AB2: =MIN(MAX(S2,PERCENTILE(S$2:S$612,0.005)),PERCENTILE(S$2:S$612,0.995)) -> 0.79883434 | AC2: =MIN(MAX(T2,PERCENTILE(T$2:T$612,0.005)),PERCENTILE(T$2:T$612,0.995)) -> 0.018055431
A3: 2 | B3: 1 | C3: ABBEYBANK | D3: Abbey Mortgage Bank Plc | E3: FINANCIAL SERVICES | F3: 2022 | G3: 0 | H3: 0 | I3: 0 | J3: 0 | K3: 10153846154 | L3: 1.6998 | M3: 17259508 | N3: 32159818 | O3: 39858233 | P3: 766160 | Q3: 1.2398775 | R3: 17.50084 | S3: 0.80685509 | T3: 0.019222127 | U3: 1991 | V3: 31 | W3: 1 | X3: PricewaterhouseCoopers | Y3: Market cap Dec-31-2022 ~17.26B NGN. Share_Price_YearEnd = Dec-31 market cap / Shares_Outstanding, market cap from S&P Global Market Intelligence (via stockanalysis.com). MEDIUM-HIGH confidence (billions-precision source rounding). | SDQ/CDQ disclosure coding, IFRS_S1S2_Adopter_Dummy, Board_Independence and Ownership_Concentration for FY2022 NOT YET CODED: no text-extractable full Annual Report was located this pass (AfricanFinancials' document page links to a Google-Drive-hosted PDF with no extractable text, consistent with the barrier seen elsewhere this session; no AnyFlip or NGX-doclib mirror found for this specific year). Flagged for a follow-up attempt. | Board_Independence=12.5% (1 Independent NED [High Chief Samuel Oni] of 8 total board members as at 31-Dec-2022, per FY2022 Annual Report Corporate Information/Directors list [doclib.ngxgroup.com #38233] -- Mr Madu Hamman [ex-officio MD/CEO] retired 14-Apr-2022 per Corporate Information footnote, excluded from year-end count). Ownership_Concentration=16.54% (VFD Group Plc, largest single substantial (>5%) shareholder as at 31-Dec-2022, per Report of the Directors 'Analysis of Shareholders' / substantial-interest table, same FY2022 AR -- comparative 31-Dec-2021 column in same table shows VFD=39.6%, consistent with the independently-confirmed FY2021 value already in row 2, cross-validating the table's year-column order; Madonna Ashib Comm. Enterprise Ltd fell to ~4% in 2022, below the 5% disclosure threshold that year, likely due to a large share issuance that roughly doubled shares outstanding between FY2021 and FY2022 per the share-capital-history note in the same filing). | Z3: ok | AA3: =MIN(MAX(Q3,PERCENTILE(Q$2:Q$612,0.005)),PERCENTILE(Q$2:Q$612,0.995)) -> 1.2398775 | AB3: =MIN(MAX(S3,PERCENTILE(S$2:S$612,0.005)),PERCENTILE(S$2:S$612,0.995)) -> 0.80685509 | AC3: =MIN(MAX(T3,PERCENTILE(T$2:T$612,0.005)),PERCENTILE(T$2:T$612,0.995)) -> 0.019222127
A4: 3 | B4: 1 | C4: ABBEYBANK | D4: Abbey Mortgage Bank Plc | E4: FINANCIAL SERVICES | F4: 2023 | G4: 1 | H4: 0 | I4: 10 | J4: 0 | K4: 10153846154 | L4: 2.2198 | M4: 22539508 | N4: 48972544 | O4: 57552242 | P4: 871284 | Q4: 1.2425589 | R4: 17.868204 | S4: 0.85092331 | T4: 0.015139011 | U4: 1991 | V4: 32 | W4: 1 | X4: PricewaterhouseCoopers | Y4: Market cap Dec-31-2023 ~22.54B NGN. Share_Price_YearEnd = Dec-31 market cap / Shares_Outstanding, market cap from S&P Global Market Intelligence (via stockanalysis.com). MEDIUM-HIGH confidence (billions-precision source rounding). | Board_Independence=11.11% (1 Independent NED [Onyejekwe] of 9 total board members as at 31-Dec-2023 -- Adenike Kuti's independent-NED appointment was effective 1-Jan-2024, per FY2024 AR 'Changes in Directorate' note, so she was not yet on the board at FY2023 year-end; Obinna Ufudo had joined 25-Jul-2023, included). Ownership_Concentration=37.77% (VFD Group Plc, largest shareholder, from FY2024 AR's own 'As at 31 December 2023' comparative substantial-interest table -- same source document, comparative column, not yet a separately-read FY2023 Annual Report). SDQ/CDQ items for FY2023 NOT YET CODED -- require the actual FY2023 Annual Report narrative (governance/risk/metrics text), which this comparative-column data alone does not provide. | Ownership_Concentration figure independently reconfirmed from the FY2023 Annual Report itself (VFD Group Plc 37.77% as at 31-Dec-2023, anyflip.com/ukxce/clsu). SDQ/CDQ full coding and a reliable Board_Independence figure for FY2023 remain OUTSTANDING: this AnyFlip capture's text layer covers the Report of the Directors and financial statements but NOT the Corporate Governance Report / Board Evaluation / Enterprise Risk Management Policy pages (pp.~10-34) that the other years' captures included -- those pages did not return extractable text in this fetch. Board changes noted in the Report of Directors (Nonso Okpala resigned, Obinna Ufudo appointed during the year; Emmanuel Ivi and Olufemi Soewu retired effective 31-Dec-2023) are insufficient alone to reconstruct a reliable Independent-NED count. Genuine access gap, not yet resolved -- flagged for a follow-up attempt via an alternate source or browser-rendered view. | Z4: ok | AA4: =MIN(MAX(Q4,PERCENTILE(Q$2:Q$612,0.005)),PERCENTILE(Q$2:Q$612,0.995)) -> 1.2425589 | AB4: =MIN(MAX(S4,PERCENTILE(S$2:S$612,0.005)),PERCENTILE(S$2:S$612,0.995)) -> 0.85092331 | AC4: =MIN(MAX(T4,PERCENTILE(T$2:T$612,0.005)),PERCENTILE(T$2:T$612,0.995)) -> 0.015139011
A5: 4 | B5: 1 | C5: ABBEYBANK | D5: Abbey Mortgage Bank Plc | E5: FINANCIAL SERVICES | F5: 2024 | G5: 1 | H5: 0 | I5: 10 | J5: 0 | K5: 10153846154 | L5: 3 | M5: 30461538 | N5: 75019725 | O5: 84251461 | P5: 1068195 | Q5: 1.2519814 | R5: 18.249316 | S5: 0.8904264 | T5: 0.012678653 | U5: 1991 | V5: 33 | W5: 1 | X5: PricewaterhouseCoopers | Y5: Share_Price_YearEnd=3.00 cross-checked against Dec-31-2024 market cap ~30.46B NGN / 10,153,846,154 shares (stockanalysis.com / S&P Global Market Intelligence). HIGH confidence. | Board_Independence=20.0% (2 Independent Non-Executive Directors [Onyejekwe, Kuti] of 10 total board members as at 31-Dec-2024, per Corporate Governance Report p.11: 'the Board was made up of a Non-Executive Chairman, five (5) Non-Executive Directors, two (2) Executive Directors and two (2) Independent Non-Executive Director'). Ownership_Concentration=37.77% (largest single substantial (>5%) shareholder, VFD Group Plc, per Report of the Directors 'Substantial interest in shares' table, p.3 -- convention: % held by the single largest disclosed shareholder, since only 2 shareholders crossed the 5% disclosure threshold this year; combined top-2 would be 51.99% if a top-N convention is preferred instead). | IFRS_S1S2_Adopter_Dummy=0 (methodology confirmed with user): no explicit or implied voluntary IFRS S1/S2 implementation found in the FY2024 Annual Report -- CDQ=0/15 and no mention of IFRS S1/S2/ISSB anywhere in the document, so neither the explicit-statement nor the structural-alignment test is met. | Z5: ok | AA5: =MIN(MAX(Q5,PERCENTILE(Q$2:Q$612,0.005)),PERCENTILE(Q$2:Q$612,0.995)) -> 1.2519814 | AB5: =MIN(MAX(S5,PERCENTILE(S$2:S$612,0.005)),PERCENTILE(S$2:S$612,0.995)) -> 0.8904264 | AC5: =MIN(MAX(T5,PERCENTILE(T$2:T$612,0.005)),PERCENTILE(T$2:T$612,0.995)) -> 0.012678653
A6: 5 | B6: 1 | C6: ABBEYBANK | D6: Abbey Mortgage Bank Plc | E6: FINANCIAL SERVICES | F6: 2025 | G6: 1 | H6: 0 | I6: 0 | J6: 0 | K6: 10153846154 | L6: 6.4 | M6: 64984615 | N6: 154067848 | O6: 165570637 | P6: 2880283 | Q6: 1.3230152 | R6: 18.924908 | S6: 0.9305264 | T6: 0.017396098 | U6: 1991 | V6: 34 | W6: 1 | X6: PricewaterhouseCoopers | Y6: UNAUDITED - provisional pending final Annual Report | SDQ/CDQ disclosure coding, IFRS_S1S2_Adopter_Dummy, Board_Independence and Ownership_Concentration for FY2025 NOT YET CODED -- genuine access gap. The NGX doclib filing for this year is a condensed UNAUDITED financial statement with no Corporate Governance Report, Board Evaluation, or Enterprise Risk Management Policy section (confirmed via full-text search, zero matches). The full audited Annual Report is hosted only as a Google Drive embed with no extractable text. AfricanFinancials' own summary page for this filing is explicitly self-labelled as AI-generated ('This summary has been generated by an AI model... may contain errors or omissions') and was deliberately NOT used as a coding source, since scoring a disclosure-quality instrument off another AI's summary rather than the primary document would undermine the reliability of the construct. Flagged for a follow-up attempt via an alternate source or browser-rendered view of the Google Drive document. | Ownership_Concentration=22.50% (VFD Group Plc, largest single substantial (>5%) shareholder as at 31-Dec-2025, per 'Shareholding Structure and Free Float Status' / Substantial Shareholding table, Note 41, in the FY2025 condensed unaudited financial statements [doclib.ngxgroup.com #45885] -- same table's 2024 comparative column shows VFD=37.77%, matching row 5's independently-sourced figure, cross-validating; Madonna Ashib Comm. Enterprise Ltd held steady at 14.23% both years, below VFD). Board_Independence LEFT BLANK -- genuine gap: this FY2025 filing is a condensed unaudited financial statement with no Corporate Governance Report / Board of Directors listing section (full-text search for 'Independent' returns zero matches); the full audited FY2025 Annual Report was not available as a text-extractable primary source this session (only a non-extractable Google Drive embed found). Not inferred from the Directors' Shareholdings list (10 names, no role/independence labels given there). | Z6: ok | AA6: =MIN(MAX(Q6,PERCENTILE(Q$2:Q$612,0.005)),PERCENTILE(Q$2:Q$612,0.995)) -> 1.3230152 | AB6: =MIN(MAX(S6,PERCENTILE(S$2:S$612,0.005)),PERCENTILE(S$2:S$612,0.995)) -> 0.9305264 | AC6: =MIN(MAX(T6,PERCENTILE(T$2:T$612,0.005)),PERCENTILE(T$2:T$612,0.995)) -> 0.017396098
A7: 6 | B7: 2 | C7: ABCTRANS | D7: ABC Transport Plc | E7: SERVICES | F7: 2021 | G7: 0 | H7: 0 | I7: 5 | J7: 0 | K7: 1657700000 | L7: 0.31 | M7: 513887 | N7: 5022365 | O7: 6081390 | P7: -153160 | Q7: 0.91035964 | R7: 15.620744 | S7: 0.82585807 | T7: -0.025185032 | U7: 1993 | V7: 28 | W7: 0 | X7: Forvis Mazars | Y7: Shares rose mid-year via rights issue in 2022, not 2021 - use 1,657,700,000 for FY2021 Market cap Dec-31-2021 ~0.514B NGN. Share_Price_YearEnd = Dec-31 market cap / Shares_Outstanding, market cap from S&P Global Market Intelligence (via stockanalysis.com). MEDIUM-HIGH confidence (billions-precision source rounding). | SDQ/CDQ disclosure coding NOT YET DONE: no text-extractable full Annual Report located this pass (the AfricanFinancials document page for this ticker/period links to a Google-Drive-hosted PDF with no extractable text; no NGX-doclib mirror found for this specific year despite a targeted search). Genuine access gap, flagged for a follow-up attempt via an alternate source or browser-rendered view. | Board_Independence and Ownership_Concentration LEFT BLANK for FY2021 -- genuine gap: source document [doclib.ngxgroup.com #38087, FY2021-2022 consolidated FS] contains 'Report of the Directors' with a Directors' Shareholdings table only (direct/indirect interests of 8 named directors), but no role labels (Chairman/Executive/Non-Executive/Independent) are stated anywhere in the document for FY2021, and no substantial/major-shareholder (5%+) disclosure table is present at all. Full-text search for 'Independent Non-Executive' and 'Substantial' returns no governance-relevant matches. Not inferred. | Z7: ok | AA7: =MIN(MAX(Q7,PERCENTILE(Q$2:Q$612,0.005)),PERCENTILE(Q$2:Q$612,0.995)) -> 0.91035964 | AB7: =MIN(MAX(S7,PERCENTILE(S$2:S$612,0.005)),PERCENTILE(S$2:S$612,0.995)) -> 0.82585807 | AC7: =MIN(MAX(T7,PERCENTILE(T$2:T$612,0.005)),PERCENTILE(T$2:T$612,0.995)) -> -0.025185032
A8: 7 | B8: 2 | C8: ABCTRANS | D8: ABC Transport Plc | E8: SERVICES | F8: 2022 | G8: 0 | H8: 0 | I8: 0 | J8: 0 | K8: 2392622000 | L8: 0.25 | M8: 598155.5 | N8: 5385835 | O8: 6642902 | P8: 15878 | Q8: 0.90080969 | R8: 15.709059 | S8: 0.81076539 | T8: 0.0023902204 | U8: 1993 | V8: 29 | W8: 0 | X8: Forvis Mazars | Y8: Rights issue during 2022 raised shares from 1.66bn to 2.39bn Market cap Dec-31-2022 ~0.598B NGN. Share_Price_YearEnd = Dec-31 market cap / Shares_Outstanding, market cap from S&P Global Market Intelligence (via stockanalysis.com). MEDIUM-HIGH confidence (billions-precision source rounding). | SDQ/CDQ fully coded this pass, all zero -- thin disclosure, no dedicated governance/ESG sections in this filing. Board_Independence/Ownership_Concentration not disclosed in this document, left blank (optional field). | Board_Independence and Ownership_Concentration LEFT BLANK for FY2022 -- same genuine gap as FY2021: source document [doclib.ngxgroup.com #38087] has no director-role labels (no 'Independent' designation used anywhere for any director in this filing) and no substantial-shareholder disclosure table. Not inferred. | Z8: ok | AA8: =MIN(MAX(Q8,PERCENTILE(Q$2:Q$612,0.005)),PERCENTILE(Q$2:Q$612,0.995)) -> 0.90080969 | AB8: =MIN(MAX(S8,PERCENTILE(S$2:S$612,0.005)),PERCENTILE(S$2:S$612,0.995)) -> 0.81076539 | AC8: =MIN(MAX(T8,PERCENTILE(T$2:T$612,0.005)),PERCENTILE(T$2:T$612,0.995)) -> 0.0023902204
A9: 8 | B9: 2 | C9: ABCTRANS | D9: ABC Transport Plc | E9: SERVICES | F9: 2023 | G9: 1 | H9: 0 | I9: 5 | J9: 0 | K9: 2392622000 | L9: 0.8108 | M9: 1939937.9 | N9: 6407895 | O9: 7023496 | P9: -175326 | Q9: 1.1885581 | R9: 15.764772 | S9: 0.9123512 | T9: -0.024962782 | U9: 1993 | V9: 30 | W9: 0 | X9: Forvis Mazars | Y9: Market cap Dec-31-2023 ~1.940B NGN. Share_Price_YearEnd = Dec-31 market cap / Shares_Outstanding, market cap from S&P Global Market Intelligence (via stockanalysis.com). MEDIUM-HIGH confidence (billions-precision source rounding). | SDQ/CDQ disclosure coding NOT YET DONE: no text-extractable full Annual Report located this pass (the AfricanFinancials document page for this ticker/period links to a Google-Drive-hosted PDF with no extractable text; no NGX-doclib mirror found for this specific year despite a targeted search). Genuine access gap, flagged for a follow-up attempt via an alternate source or browser-rendered view. | Board_Independence and Ownership_Concentration LEFT BLANK for FY2023 -- genuine gap: no text-extractable standalone FY2023 Annual Report was located (NGX doclib and AfricanFinancials only hold FY2022 [#38087], FY2024 [#43623], and FY2025 [#46506] filings for ABC Transport Plc; the only FY2023 NGX doclib item found is a 2023 AGM Resolutions/Corporate Actions notice [#39968], which does not contain a Directors list, Corporate Governance Report, or shareholding table). The FY2024 AR [#43623] gives only the current (2024) board and does not restate a FY2023 board list. Flagged for a follow-up attempt if a standalone FY2023 AR becomes accessible. | Z9: ok | AA9: =MIN(MAX(Q9,PERCENTILE(Q$2:Q$612,0.005)),PERCENTILE(Q$2:Q$612,0.995)) -> 1.1885581 | AB9: =MIN(MAX(S9,PERCENTILE(S$2:S$612,0.005)),PERCENTILE(S$2:S$612,0.995)) -> 0.9123512 | AC9: =MIN(MAX(T9,PERCENTILE(T$2:T$612,0.005)),PERCENTILE(T$2:T$612,0.995)) -> -0.024962782
A10: 9 | B10: 2 | C10: ABCTRANS | D10: ABC Transport Plc | E10: SERVICES | F10: 2024 | G10: 1 | H10: 0 | I10: 0 | J10: 0 | K10: 2392622000 | L10: 1.2288 | M10: 2940053.9 | N10: 10734736 | O10: 12003865 | P10: 532807 | Q10: 1.1391989 | R10: 16.300739 | S10: 0.8942733 | T10: 0.044386287 | U10: 1993 | V10: 31 | W10: 0 | X10: Forvis Mazars | Y10: Market cap Dec-31-2024 ~2.940B NGN. Share_Price_YearEnd = Dec-31 market cap / Shares_Outstanding, market cap from S&P Global Market Intelligence (via stockanalysis.com). MEDIUM-HIGH confidence (billions-precision source rounding). | SDQ/CDQ fully coded this pass, all zero. IFRS_S1S2_Adopter_Dummy=0 EXPLICITLY EVIDENCED (identical 'not yet adopted, mandatory 2028' note as FY2025). Board_Independence=12.5% (1 Independent NED of 8 total board members). Ownership_Concentration not disclosed in this document, left blank (optional field). | Ownership_Concentration LEFT BLANK for FY2024 -- confirmed genuine gap: full-text search of the FY2024 Annual Report [doclib.ngxgroup.com #43623] for 'Substantial', 'shareholding', '% of', 'Analysis of' returns no substantial/major-shareholder (5%+) disclosure table anywhere in the filing (Report of the Directors covers Directors, Legal Form, Principal Activities, Directors' Responsibilities only -- no shareholding-analysis section). Board_Independence=12.5% value already in this cell was independently reconfirmed from this same document's Corporate Information page (line 42-49): 8 directors total (Obayomi-Chairman, Jude Nneji-MD, Rex Okoro-ED, Francis Nneji-NED, Kabiru Yusuf-NED, Bamidele Asije-NED, Ifeoma Adeoye-NED, Emmanuel Chilaka Nwanna-Independent NED), 1 explicitly labelled Independent Non-Executive Director = 1/8 = 12.5%. | Z10: ok | AA10: =MIN(MAX(Q10,PERCENTILE(Q$2:Q$612,0.005)),PERCENTILE(Q$2:Q$612,0.995)) -> 1.1391989 | AB10: =MIN(MAX(S10,PERCENTILE(S$2:S$612,0.005)),PERCENTILE(S$2:S$612,0.995)) -> 0.8942733 | AC10: =MIN(MAX(T10,PERCENTILE(T$2:T$612,0.005)),PERCENTILE(T$2:T$612,0.995)) -> 0.044386287
A11: 10 | B11: 2 | C11: ABCTRANS | D11: ABC Transport Plc | E11: SERVICES | F11: 2025 | G11: 1 | H11: 0 | I11: 0 | J11: 0 | K11: 2392622000 | L11: 4.1001 | M11: 9809989.5 | N11: 12152000 | O11: 14462677 | P11: 971297 | Q11: 1.5185287 | R11: 16.487082 | S11: 0.84023172 | T11: 0.067158867 | U11: 1993 | V11: 32 | W11: 0 | X11: Forvis Mazars | Y11: Audited, unmodified opinion 31-Mar-2026 Market cap Dec-31-2025 ~9.810B NGN. Share_Price_YearEnd = Dec-31 market cap / Shares_Outstanding, market cap from S&P Global Market Intelligence (via stockanalysis.com). MEDIUM-HIGH confidence (billions-precision source rounding). | SDQ/CDQ fully coded this pass, all zero. IFRS_S1S2_Adopter_Dummy=0 EXPLICITLY EVIDENCED (filing states IFRS S1 'not yet adopted', mandatory 2028 -- see Coding Sheet note for full quote). Board_Independence=12.5% (1 Independent NED of 8 total board members, per Corporate Information page). Ownership_Concentration not disclosed in this document, left blank (optional field). | Ownership_Concentration LEFT BLANK for FY2025 -- confirmed genuine gap: full-text search of the FY2025 Annual Report [doclib.ngxgroup.com #46506] for 'Substantial'/shareholding-analysis terms returns no substantial/major-shareholder (5%+) disclosure table anywhere in the filing. Board_Independence=12.5% value already in this cell reconfirmed from this same document's Corporate Information page (line 43-50): same 8-director board as FY2024 (Obayomi-Chairman, Jude Nneji-MD, Rex Okoro-ED, Francis Nneji/Kabiru Yusuf/Bamidele Asije/Ifeoma Adeoye-NEDs, Emmanuel Chilaka Nwanna-Independent NED), 1/8 = 12.5%. | Z11: ok | AA11: =MIN(MAX(Q11,PERCENTILE(Q$2:Q$612,0.005)),PERCENTILE(Q$2:Q$612,0.995)) -> 1.5185287 | AB11: =MIN(MAX(S11,PERCENTILE(S$2:S$612,0.005)),PERCENTILE(S$2:S$612,0.995)) -> 0.84023172 | AC11: =MIN(MAX(T11,PERCENTILE(T$2:T$612,0.005)),PERCENTILE(T$2:T$612,0.995)) -> 0.067158867
A12: 11 | B12: 3 | C12: ACADEMY | D12: Academy Press Plc | E12: SERVICES | F12: 2021 | G12: 0 | H12: 0 | I12: 0 | J12: 0 | K12: 604800000 | L12: 0.5 | M12: 302400 | N12: 2267930 | O12: 2278858 | P12: -205452 | Q12: 1.1279027 | R12: 14.639185 | S12: 0.99520462 | T12: -0.090155683 | U12: 1964 | V12: 57 | W12: 1 | X12: Ernst & Young | Y12: FYE 31-March not December. Net income unresolved - retained earnings restated inconsistently across filings Share_Price_YearEnd = calendar Dec-31 proxy. Share_Price_YearEnd = Dec-31 market cap / shares outstanding, market cap from S&P Global Market Intelligence (via stockanalysis.com). Net_Income RESOLVED: -205,452 (Group, net LOSS) from Academy Press FY2022 Audited AR comparative column. Source: NGX doclib primary filings. SDQ/CDQ coding NOT YET DONE - genuine access gap: NGX doclib has no full-text FY2021 Annual Report (only a Sept-2021 Q2 interim, condensed, no CG Report/Environmental Policy narrative); AfricanFinancials 2021 AR (ng-academ-2021-ar-00, published 2021-10-11) links only to a Google Drive-hosted PDF with no extractable text. No AnyFlip or other mirror located via search. Documented as access barrier, consistent with methodology used for ABBEYBANK/ABCTRANS gap years. | Board_Independence and Ownership_Concentration LEFT BLANK for FY2021 (FYE 31-Mar-2021) -- genuine access gap reconfirmed this pass: NGX doclib has no full-text FY2021 Annual Report (only a condensed Sept-2021 Q2 interim with no governance/shareholding section); AfricanFinancials' FY2021 AR links only to a non-extractable Google Drive PDF. No alternate text-extractable primary source located. | Z12: ok | AA12: =MIN(MAX(Q12,PERCENTILE(Q$2:Q$612,0.005)),PERCENTILE(Q$2:Q$612,0.995)) -> 1.1279027 | AB12: =MIN(MAX(S12,PERCENTILE(S$2:S$612,0.005)),PERCENTILE(S$2:S$612,0.995)) -> 0.99520462 | AC12: =MIN(MAX(T12,PERCENTILE(T$2:T$612,0.005)),PERCENTILE(T$2:T$612,0.995)) -> -0.090155683
A13: 12 | B13: 3 | C13: ACADEMY | D13: Academy Press Plc | E13: SERVICES | F13: 2022 | G13: 0 | H13: 0 | I13: 0 | J13: 0 | K13: 604800000 | L13: 1.6125 | M13: 975240 | N13: 2107843 | O13: 2357293 | P13: 238523 | Q13: 1.3078913 | R13: 14.673024 | S13: 0.89417947 | T13: 0.10118513 | U13: 1964 | V13: 58 | W13: 1 | X13: Ernst & Young | Y13: FYE 31-March. Needs re-verification - sourced from unaudited interim, same pattern proved wrong for 2023 Share_Price_YearEnd = calendar Dec-31 proxy. Share_Price_YearEnd = Dec-31 market cap / shares outstanding, market cap from S&P Global Market Intelligence (via stockanalysis.com). SDQ/CDQ coding NOT YET DONE - genuine access gap: AfricanFinancials 2022 AR (ng-academ-2022-ar-00, published 2023-01-17) links only to a Google Drive-hosted PDF with no extractable text; no NGX doclib full AR or AnyFlip mirror located via search. Documented as access barrier, consistent with methodology used for ABBEYBANK/ABCTRANS gap years. | Board_Independence and Ownership_Concentration LEFT BLANK for FY2022 (FYE 31-Mar-2022) -- genuine access gap reconfirmed this pass: AfricanFinancials' FY2022 AR links only to a non-extractable Google Drive PDF; no NGX-doclib full AR or other text-extractable mirror located for this exact FYE. | Z13: ok | AA13: =MIN(MAX(Q13,PERCENTILE(Q$2:Q$612,0.005)),PERCENTILE(Q$2:Q$612,0.995)) -> 1.3078913 | AB13: =MIN(MAX(S13,PERCENTILE(S$2:S$612,0.005)),PERCENTILE(S$2:S$612,0.995)) -> 0.89417947 | AC13: =MIN(MAX(T13,PERCENTILE(T$2:T$612,0.005)),PERCENTILE(T$2:T$612,0.995)) -> 0.10118513
... A579: 685 | B579: 137 | C579: UPDC | D579: UPDC Plc | E579: CONSTRUCTION/REAL ESTATE | F579: 2025 | G579: 1 | H579: 0 | I579: 0 | J579: 0 | K579: 18560000000 | L579: 4.8998 | M579: 90940288 | N579: 18538000 | O579: 29989000 | P579: 974620 | Q579: 3.6506148 | R579: 17.216341 | S579: 0.61815999 | T579: 0.03249925 | U579: 1997 | V579: 28 | W579: 0 | X579: UNRESOLVED | Y579: UPDC Plc FY2025: TA/TL/NI from stockanalysis.com balance sheet/income statement (millions NGN, x1000 applied). Shares_Outstanding = period-end Total Common Shares Outstanding. Share_Price_YearEnd = stockanalysis.com year-end market cap / shares. Auditor: UNRESOLVED despite extensive search (MCNICHOLS precedent applied), LOW confidence on auditor field only (financial figures themselves are HIGH confidence, well-covered). Turnaround from FY2021 net loss to sustained profitability; large FY2025 market-cap re-rating. | Z579: BLS | AA579: =MIN(MAX(Q579,PERCENTILE(Q$2:Q$612,0.005)),PERCENTILE(Q$2:Q$612,0.995)) -> 3.6506148 | AB579: =MIN(MAX(S579,PERCENTILE(S$2:S$612,0.005)),PERCENTILE(S$2:S$612,0.995)) -> 0.61815999 | AC579: =MIN(MAX(T579,PERCENTILE(T$2:T$612,0.005)),PERCENTILE(T$2:T$612,0.995)) -> 0.03249925
A580: 691 | B580: 139 | C580: UPL | D580: University Press Plc | E580: SERVICES | F580: 2021 | G580: 0 | H580: 0 | I580: 0 | J580: 0 | K580: 431409504 | L580: 2.94 | M580: 1268343.9 | N580: 1124536 | O580: 3785015 | P580: 57106 | Q580: 0.63219827 | R580: 15.14656 | S580: 0.29710213 | T580: 0.015087391 | U580: 1978 | V580: 43 | X580: PKF Professional Services | Y580: RESOLVED, HIGH confidence - University Press Plc FY2021 (FYE 31-Mar-2021) Audited FS, NGX doclib primary source. TA-TL=2,660,479 matches reported 'Total net assets' in the same segment note (a separate 'Total equity' note shows 2,663,962, a 0.13% variance - used the internally-consistent segment figures). Share_Price_YearEnd remains an open gap: only a calendar Dec-31-2021 market cap was found (N1.27bn, implying ~N2.94), which is a Dec value not the FYE Mar-2021 point - not entered to avoid mixing reference dates. Source: NGX doclib primary filings. | Share_Price_YearEnd=2.94 sourced from the firm's own corporate/investor-relations website, manually verified by user (Ben) and supplied directly, 17-Aug-2026 -- resolves the previously-flagged Share_Price_YearEnd open gap. Market_Value_Equity and Tobin_Q recompute automatically via existing workbook formulas. | Z580: ok | AA580: =MIN(MAX(Q580,PERCENTILE(Q$2:Q$612,0.005)),PERCENTILE(Q$2:Q$612,0.995)) -> 0.63219827 | AB580: =MIN(MAX(S580,PERCENTILE(S$2:S$612,0.005)),PERCENTILE(S$2:S$612,0.995)) -> 0.29710213 | AC580: =MIN(MAX(T580,PERCENTILE(T$2:T$612,0.005)),PERCENTILE(T$2:T$612,0.995)) -> 0.015087391
A581: 692 | B581: 139 | C581: UPL | D581: University Press Plc | E581: SERVICES | F581: 2022 | G581: 0 | H581: 0 | I581: 0 | J581: 0 | K581: 431410000 | L581: 2.9438 | M581: 1269984.8 | N581: 1115000 | O581: 4287000 | P581: 207490 | Q581: 0.55632954 | R581: 15.271098 | S581: 0.26008864 | T581: 0.048399813 | U581: 1978 | V581: 44 | W581: 0 | X581: PKF Professional Services | Y581: University Press Plc FY2022: TA/TL/NI from stockanalysis.com balance sheet/income statement (millions NGN, x1000 applied). Shares_Outstanding = period-end Total Common Shares Outstanding. Share_Price_YearEnd = stockanalysis.com year-end market cap / shares. Non-standard FYE (Apr-Mar): FYE-labelled year (ending Mar-2022) maps directly to study Year 2022; Share_Price_YearEnd uses the nearest-preceding-Dec-31 market cap (Dec-31-2021). Auditor: PKF Professional Services (non-Big4), confirmed. MEDIUM-HIGH confidence. | Z581: ok | AA581: =MIN(MAX(Q581,PERCENTILE(Q$2:Q$612,0.005)),PERCENTILE(Q$2:Q$612,0.995)) -> 0.55632954 | AB581: =MIN(MAX(S581,PERCENTILE(S$2:S$612,0.005)),PERCENTILE(S$2:S$612,0.995)) -> 0.26008864 | AC581: =MIN(MAX(T581,PERCENTILE(T$2:T$612,0.005)),PERCENTILE(T$2:T$612,0.995)) -> 0.048399813
A582: 693 | B582: 139 | C582: UPL | D582: University Press Plc | E582: SERVICES | F582: 2023 | G582: 1 | H582: 0 | I582: 0 | J582: 0 | K582: 431410000 | L582: 1.9 | M582: 819679 | N582: 964620 | O582: 4236000 | P582: 142290 | Q582: 0.42122262 | R582: 15.25913 | S582: 0.22771955 | T582: 0.033590652 | U582: 1978 | V582: 45 | W582: 0 | X582: PKF Professional Services | Y582: University Press Plc FY2023: TA/TL/NI from stockanalysis.com balance sheet/income statement (millions NGN, x1000 applied). Shares_Outstanding = period-end Total Common Shares Outstanding. Share_Price_YearEnd = stockanalysis.com year-end market cap / shares. Non-standard FYE (Apr-Mar): FYE-labelled year (ending Mar-2023) maps directly to study Year 2023; Share_Price_YearEnd uses the nearest-preceding-Dec-31 market cap (Dec-31-2022). Auditor: PKF Professional Services (non-Big4), confirmed. MEDIUM-HIGH confidence. | Z582: ok | AA582: =MIN(MAX(Q582,PERCENTILE(Q$2:Q$612,0.005)),PERCENTILE(Q$2:Q$612,0.995)) -> 0.42843805 | AB582: =MIN(MAX(S582,PERCENTILE(S$2:S$612,0.005)),PERCENTILE(S$2:S$612,0.995)) -> 0.22771955 | AC582: =MIN(MAX(T582,PERCENTILE(T$2:T$612,0.005)),PERCENTILE(T$2:T$612,0.995)) -> 0.033590652
A583: 694 | B583: 139 | C583: UPL | D583: University Press Plc | E583: SERVICES | F583: 2024 | G583: 1 | H583: 0 | I583: 5 | J583: 0 | K583: 431410000 | L583: 2.4107 | M583: 1040000.1 | N583: 2041000 | O583: 5112000 | P583: -157720 | Q583: 0.60269955 | R583: 15.447101 | S583: 0.39925665 | T583: -0.030852895 | U583: 1978 | V583: 46 | W583: 0 | X583: PKF Professional Services | Y583: University Press Plc FY2024: TA/TL/NI from stockanalysis.com balance sheet/income statement (millions NGN, x1000 applied). Shares_Outstanding = period-end Total Common Shares Outstanding. Share_Price_YearEnd = stockanalysis.com year-end market cap / shares. Non-standard FYE (Apr-Mar): FYE-labelled year (ending Mar-2024) maps directly to study Year 2024; Share_Price_YearEnd uses the nearest-preceding-Dec-31 market cap (Dec-31-2023). Auditor: PKF Professional Services (non-Big4), confirmed. MEDIUM-HIGH confidence. | Z583: ok | AA583: =MIN(MAX(Q583,PERCENTILE(Q$2:Q$612,0.005)),PERCENTILE(Q$2:Q$612,0.995)) -> 0.60269955 | AB583: =MIN(MAX(S583,PERCENTILE(S$2:S$612,0.005)),PERCENTILE(S$2:S$612,0.995)) -> 0.39925665 | AC583: =MIN(MAX(T583,PERCENTILE(T$2:T$612,0.005)),PERCENTILE(T$2:T$612,0.995)) -> -0.030852895
A584: 695 | B584: 139 | C584: UPL | D584: University Press Plc | E584: SERVICES | F584: 2025 | G584: 1 | H584: 0 | I584: 5 | J584: 0 | K584: 431410000 | L584: 3.8478 | M584: 1659979.4 | N584: 1099000 | O584: 4508000 | P584: 450630 | Q584: 0.6120185 | R584: 15.321364 | S584: 0.24378882 | T584: 0.099962289 | U584: 1978 | V584: 47 | W584: 0 | X584: PKF Professional Services | Y584: University Press Plc FY2025: TA/TL/NI from stockanalysis.com balance sheet/income statement (millions NGN, x1000 applied). Shares_Outstanding = period-end Total Common Shares Outstanding. Share_Price_YearEnd = stockanalysis.com year-end market cap / shares. Non-standard FYE (Apr-Mar): FYE-labelled year (ending Mar-2025) maps directly to study Year 2025; Share_Price_YearEnd uses the nearest-preceding-Dec-31 market cap (Dec-31-2024). Auditor: PKF Professional Services (non-Big4), confirmed. MEDIUM-HIGH confidence. | Z584: ok | AA584: =MIN(MAX(Q584,PERCENTILE(Q$2:Q$612,0.005)),PERCENTILE(Q$2:Q$612,0.995)) -> 0.6120185 | AB584: =MIN(MAX(S584,PERCENTILE(S$2:S$612,0.005)),PERCENTILE(S$2:S$612,0.995)) -> 0.24378882 | AC584: =MIN(MAX(T584,PERCENTILE(T$2:T$612,0.005)),PERCENTILE(T$2:T$612,0.995)) -> 0.099962289
A585: 696 | B585: 140 | C585: VERITASKAP | D585: Veritas Kapital Assurance Plc | E585: FINANCIAL SERVICES | F585: 2021 | G585: 0 | H585: 0 | I585: 0 | J585: 0 | K585: 13867000000 | L585: 0.2099 | M585: 2910683.3 | N585: 5762000 | O585: 16565000 | P585: 505300 | Q585: 0.52355468 | R585: 16.622803 | S585: 0.34784184 | T585: 0.030504075 | U585: 1973 | V585: 48 | W585: 1 | X585: Ernst & Young | Y585: Veritas Kapital Assurance Plc FY2021: TA/TL/NI from stockanalysis.com balance sheet/income statement (millions NGN, x1000 applied). Shares_Outstanding = period-end Total Common Shares Outstanding. Share_Price_YearEnd = stockanalysis.com year-end market cap / shares. Auditor: Ernst & Young (Big4), confirmed. HIGH confidence. | Z585: ok | AA585: =MIN(MAX(Q585,PERCENTILE(Q$2:Q$612,0.005)),PERCENTILE(Q$2:Q$612,0.995)) -> 0.52355468 | AB585: =MIN(MAX(S585,PERCENTILE(S$2:S$612,0.005)),PERCENTILE(S$2:S$612,0.995)) -> 0.34784184 | AC585: =MIN(MAX(T585,PERCENTILE(T$2:T$612,0.005)),PERCENTILE(T$2:T$612,0.995)) -> 0.030504075
A586: 697 | B586: 140 | C586: VERITASKAP | D586: Veritas Kapital Assurance Plc | E586: FINANCIAL SERVICES | F586: 2022 | G586: 0 | H586: 0 | I586: 0 | J586: 0 | K586: 13867000000 | L586: 0.1998 | M586: 2770626.6 | N586: 4791000 | O586: 17250000 | P586: 540610 | Q586: 0.43835517 | R586: 16.663323 | S586: 0.27773913 | T586: 0.03133971 | U586: 1973 | V586: 49 | W586: 1 | X586: Ernst & Young | Y586: Veritas Kapital Assurance Plc FY2022: TA/TL/NI from stockanalysis.com balance sheet/income statement (millions NGN, x1000 applied). Shares_Outstanding = period-end Total Common Shares Outstanding. Share_Price_YearEnd = stockanalysis.com year-end market cap / shares. Auditor: Ernst & Young (Big4), confirmed. HIGH confidence. | Z586: ok | AA586: =MIN(MAX(Q586,PERCENTILE(Q$2:Q$612,0.005)),PERCENTILE(Q$2:Q$612,0.995)) -> 0.43835517 | AB586: =MIN(MAX(S586,PERCENTILE(S$2:S$612,0.005)),PERCENTILE(S$2:S$612,0.995)) -> 0.27773913 | AC586: =MIN(MAX(T586,PERCENTILE(T$2:T$612,0.005)),PERCENTILE(T$2:T$612,0.995)) -> 0.03133971
A587: 698 | B587: 140 | C587: VERITASKAP | D587: Veritas Kapital Assurance Plc | E587: FINANCIAL SERVICES | F587: 2023 | G587: 1 | H587: 0 | I587: 0 | J587: 0 | K587: 13867000000 | L587: 0.3699 | M587: 5129403.3 | N587: 8311000 | O587: 24680000 | P587: 2575000 | Q587: 0.54458684 | R587: 17.021504 | S587: 0.33675041 | T587: 0.10433549 | U587: 1973 | V587: 50 | W587: 1 | X587: Ernst & Young | Y587: Veritas Kapital Assurance Plc FY2023: TA/TL/NI from stockanalysis.com balance sheet/income statement (millions NGN, x1000 applied). Shares_Outstanding = period-end Total Common Shares Outstanding. Share_Price_YearEnd = stockanalysis.com year-end market cap / shares. Auditor: Ernst & Young (Big4), confirmed. HIGH confidence. | Z587: ok | AA587: =MIN(MAX(Q587,PERCENTILE(Q$2:Q$612,0.005)),PERCENTILE(Q$2:Q$612,0.995)) -> 0.54458684 | AB587: =MIN(MAX(S587,PERCENTILE(S$2:S$612,0.005)),PERCENTILE(S$2:S$612,0.995)) -> 0.33675041 | AC587: =MIN(MAX(T587,PERCENTILE(T$2:T$612,0.005)),PERCENTILE(T$2:T$612,0.995)) -> 0.10433549
A588: 699 | B588: 140 | C588: VERITASKAP | D588: Veritas Kapital Assurance Plc | E588: FINANCIAL SERVICES | F588: 2024 | G588: 1 | H588: 0 | I588: 0 | J588: 0 | K588: 13867000000 | L588: 1.3601 | M588: 18860507 | N588: 22255000 | O588: 37540000 | P588: -1224000 | Q588: 1.0952453 | R588: 17.440918 | S588: 0.59283431 | T588: -0.032605221 | U588: 1973 | V588: 51 | W588: 1 | X588: Ernst & Young | Y588: Veritas Kapital Assurance Plc FY2024: TA/TL/NI from stockanalysis.com balance sheet/income statement (millions NGN, x1000 applied). Shares_Outstanding = period-end Total Common Shares Outstanding. Share_Price_YearEnd = stockanalysis.com year-end market cap / shares. Auditor: Ernst & Young (Big4), confirmed. HIGH confidence. Large net loss driven by a -N5.65bn operating-income swing - genuine reported results. | Z588: ok | AA588: =MIN(MAX(Q588,PERCENTILE(Q$2:Q$612,0.005)),PERCENTILE(Q$2:Q$612,0.995)) -> 1.0952453 | AB588: =MIN(MAX(S588,PERCENTILE(S$2:S$612,0.005)),PERCENTILE(S$2:S$612,0.995)) -> 0.59283431 | AC588: =MIN(MAX(T588,PERCENTILE(T$2:T$612,0.005)),PERCENTILE(T$2:T$612,0.995)) -> -0.032605221
A589: 700 | B589: 140 | C589: VERITASKAP | D589: Veritas Kapital Assurance Plc | E589: FINANCIAL SERVICES | F589: 2025 | G589: 1 | H589: 0 | I589: 5 | J589: 0 | K589: 13867000000 | L589: 1.7098 | M589: 23709797 | N589: 16270000 | O589: 35397000 | P589: 3733000 | Q589: 1.1294685 | R589: 17.382138 | S589: 0.45964347 | T589: 0.10546091 | U589: 1973 | V589: 52 | W589: 1 | X589: Ernst & Young | Y589: Veritas Kapital Assurance Plc FY2025: TA/TL/NI from stockanalysis.com balance sheet/income statement (millions NGN, x1000 applied). Shares_Outstanding = period-end Total Common Shares Outstanding. Share_Price_YearEnd = stockanalysis.com year-end market cap / shares. Auditor: Ernst & Young (Big4), confirmed. HIGH confidence. | Z589: ok | AA589: =MIN(MAX(Q589,PERCENTILE(Q$2:Q$612,0.005)),PERCENTILE(Q$2:Q$612,0.995)) -> 1.1294685 | AB589: =MIN(MAX(S589,PERCENTILE(S$2:S$612,0.005)),PERCENTILE(S$2:S$612,0.995)) -> 0.45964347 | AC589: =MIN(MAX(T589,PERCENTILE(T$2:T$612,0.005)),PERCENTILE(T$2:T$612,0.995)) -> 0.10546091
A590: 703 | B590: 141 | C590: VFDGROUP | D590: VFD Group Plc | E590: INVESTMENT | F590: 2023 | G590: 1 | H590: 0 | I590: 0 | J590: 0 | K590: 5701000000 | L590: 6.7637 | M590: 38559854 | N590: 186747000 | O590: 219277000 | P590: -2463000 | Q590: 1.0274988 | R590: 19.205846 | S590: 0.85164883 | T590: -0.011232368 | U590: 2009 | V590: 14 | W590: 1 | X590: PricewaterhouseCoopers | Y590: VFD Group Plc FY2023: TA/TL/NI from stockanalysis.com balance sheet/income statement (millions NGN, x1000 applied). Shares_Outstanding = period-end Total Common Shares Outstanding. Share_Price_YearEnd = stockanalysis.com year-end market cap / shares. Auditor: PricewaterhouseCoopers (Big4), confirmed. HIGH confidence post-listing (NGX-listed 6-Oct-2023). | Z590: ok | AA590: =MIN(MAX(Q590,PERCENTILE(Q$2:Q$612,0.005)),PERCENTILE(Q$2:Q$612,0.995)) -> 1.0274988 | AB590: =MIN(MAX(S590,PERCENTILE(S$2:S$612,0.005)),PERCENTILE(S$2:S$612,0.995)) -> 0.85164883 | AC590: =MIN(MAX(T590,PERCENTILE(T$2:T$612,0.005)),PERCENTILE(T$2:T$612,0.995)) -> -0.011232368
A591: 704 | B591: 141 | C591: VFDGROUP | D591: VFD Group Plc | E591: INVESTMENT | F591: 2024 | G591: 1 | H591: 0 | I591: 5 | J591: 0 | K591: 7601000000 | L591: 7.4003 | M591: 56249680 | N591: 237143000 | O591: 295669000 | P591: 6265000 | Q591: 0.99230112 | R591: 19.504751 | S591: 0.80205568 | T591: 0.021189235 | U591: 2009 | V591: 15 | W591: 1 | X591: PricewaterhouseCoopers | Y591: VFD Group Plc FY2024: TA/TL/NI from stockanalysis.com balance sheet/income statement (millions NGN, x1000 applied). Shares_Outstanding = period-end Total Common Shares Outstanding. Share_Price_YearEnd = stockanalysis.com year-end market cap / shares. Auditor: PricewaterhouseCoopers (Big4), confirmed. HIGH confidence post-listing (NGX-listed 6-Oct-2023). Share count increased 5,701m->7,601m (+33.3%) - flagged so not mistaken for an error. | Z591: ok | AA591: =MIN(MAX(Q591,PERCENTILE(Q$2:Q$612,0.005)),PERCENTILE(Q$2:Q$612,0.995)) -> 0.99230112 | AB591: =MIN(MAX(S591,PERCENTILE(S$2:S$612,0.005)),PERCENTILE(S$2:S$612,0.995)) -> 0.80205568 | AC591: =MIN(MAX(T591,PERCENTILE(T$2:T$612,0.005)),PERCENTILE(T$2:T$612,0.995)) -> 0.021189235
A592: 705 | B592: 141 | C592: VFDGROUP | D592: VFD Group Plc | E592: INVESTMENT | F592: 2025 | G592: 1 | H592: 0 | I592: 5 | J592: 0 | K592: 7601000000 | L592: 10.9999 | M592: 83610240 | N592: 376185000 | O592: 445806000 | P592: 7246000 | Q592: 1.0313797 | R592: 19.915394 | S592: 0.84383117 | T592: 0.016253707 | U592: 2009 | V592: 16 | W592: 1 | X592: PricewaterhouseCoopers | Y592: VFD Group Plc FY2025: TA/TL/NI from stockanalysis.com balance sheet/income statement (millions NGN, x1000 applied). Shares_Outstanding = period-end Total Common Shares Outstanding. Share_Price_YearEnd = stockanalysis.com year-end market cap / shares. Auditor: PricewaterhouseCoopers (Big4), confirmed. HIGH confidence post-listing (NGX-listed 6-Oct-2023). | Z592: ok | AA592: =MIN(MAX(Q592,PERCENTILE(Q$2:Q$612,0.005)),PERCENTILE(Q$2:Q$612,0.995)) -> 1.0313797 | AB592: =MIN(MAX(S592,PERCENTILE(S$2:S$612,0.005)),PERCENTILE(S$2:S$612,0.995)) -> 0.84383117 | AC592: =MIN(MAX(T592,PERCENTILE(T$2:T$612,0.005)),PERCENTILE(T$2:T$612,0.995)) -> 0.016253707
... A612: 725 | B612: 145 | C612: ZENITHBANK | D612: Zenith Bank Plc | E612: FINANCIAL SERVICES | F612: 2025 | G612: 1 | H612: 1 | I612: 85 | J612: 66.666667 | K612: 41070000000 | L612: 61.8456 | M612: 2539998792 | N612: 26533845000 | O612: 31458051000 | P612: 1039747000 | Q612: 0.92420995 | R612: 24.171921 | S612: 0.84346754 | T612: 0.033051857 | U612: 1990 | V612: 35 | W612: 0 | X612: UNRESOLVED | Y612: Zenith Bank Plc FY2025: TA/TL/NI from stockanalysis.com balance sheet/income statement (millions NGN, x1000 applied). Shares_Outstanding = period-end Total Common Shares Outstanding. Share_Price_YearEnd = stockanalysis.com year-end market cap / shares. Auditor: UNRESOLVED despite extensive search (MCNICHOLS precedent applied), LOW confidence on auditor field only (financial figures themselves are HIGH confidence, Tier-1 bank). Share count increased 31,396m->41,070m in FY2025 from a capital raise, not a data error. | Z612: ok | AA612: =MIN(MAX(Q612,PERCENTILE(Q$2:Q$612,0.005)),PERCENTILE(Q$2:Q$612,0.995)) -> 0.92420995 | AB612: =MIN(MAX(S612,PERCENTILE(S$2:S$612,0.005)),PERCENTILE(S$2:S$612,0.995)) -> 0.84346754 | AC612: =MIN(MAX(T612,PERCENTILE(T$2:T$612,0.005)),PERCENTILE(T$2:T$612,0.995)) -> 0.033051857

Sheet 1. Sample Profile
A1: TABLE 1: SAMPLE PROFILE
A2: Final Sample tab, all figures computed live via formula
A4: Total firm-year observations (N) | B4: =COUNTA('Final Sample'!C2:C612) -> 611
A5: Unique firms | B5: =SUMPRODUCT(1/COUNTIF('Final Sample'!C2:C612,'Final Sample'!C2:C612)) -> 128
A6: Study window | B6: 2021-2025
A7: Maximum possible panel (146 firms x 5 years) | B7: 730
A8: Realised sample as % of maximum possible | B8: =B4/730 -> 0.8369863
A10: PANEL BALANCE BY YEAR
A11: Year | B11: Firm-Years (N) | C11: % of Sample
A12: 2021 | B12: =COUNTIF('Final Sample'!$F$2:$F$612,A12) -> 118 | C12: =B12/$B$4 -> 0.19312602
A13: 2022 | B13: =COUNTIF('Final Sample'!$F$2:$F$612,A13) -> 122 | C13: =B13/$B$4 -> 0.19967267
A14: 2023 | B14: =COUNTIF('Final Sample'!$F$2:$F$612,A14) -> 122 | C14: =B14/$B$4 -> 0.19967267
A15: 2024 | B15: =COUNTIF('Final Sample'!$F$2:$F$612,A15) -> 125 | C15: =B15/$B$4 -> 0.20458265
A16: 2025 | B16: =COUNTIF('Final Sample'!$F$2:$F$612,A16) -> 124 | C16: =B16/$B$4 -> 0.20294599
A17: Total | B17: =SUM(B12:B16) -> 611 | C17: =SUM(C12:C16) -> 1
A19: SAMPLE DISTRIBUTION BY SECTOR
A20: Sector | B20: Firm-Years (N) | C20: % of Sample
A21: OIL AND GAS | B21: =COUNTIF('Final Sample'!$E$2:$E$612,A21) -> 32 | C21: =B21/$B$4 -> 0.052373159
A22: FINANCIAL SERVICES | B22: =COUNTIF('Final Sample'!$E$2:$E$612,A22) -> 196 | C22: =B22/$B$4 -> 0.3207856
A23: HEALTHCARE | B23: =COUNTIF('Final Sample'!$E$2:$E$612,A23) -> 23 | C23: =B23/$B$4 -> 0.037643208
A24: CONSUMER GOODS | B24: =COUNTIF('Final Sample'!$E$2:$E$612,A24) -> 79 | C24: =B24/$B$4 -> 0.12929624
A25: ICT | B25: =COUNTIF('Final Sample'!$E$2:$E$612,A25) -> 41 | C25: =B25/$B$4 -> 0.06710311
A26: INDUSTRIAL GOODS | B26: =COUNTIF('Final Sample'!$E$2:$E$612,A26) -> 59 | C26: =B26/$B$4 -> 0.096563011
A27: AGRICULTURE | B27: =COUNTIF('Final Sample'!$E$2:$E$612,A27) -> 25 | C27: =B27/$B$4 -> 0.04091653
A28: CONSTRUCTION/REAL ESTATE | B28: =COUNTIF('Final Sample'!$E$2:$E$612,A28) -> 17 | C28: =B28/$B$4 -> 0.027823241
A29: UTILITIES | B29: =COUNTIF('Final Sample'!$E$2:$E$612,A29) -> 6 | C29: =B29/$B$4 -> 0.0098199673
A30: INVESTMENT | B30: =COUNTIF('Final Sample'!$E$2:$E$612,A30) -> 3 | C30: =B30/$B$4 -> 0.0049099836
A31: SERVICES | B31: =COUNTIF('Final Sample'!$E$2:$E$612,A31) -> 95 | C31: =B31/$B$4 -> 0.15548282
A32: CONGLOMERATES | B32: =COUNTIF('Final Sample'!$E$2:$E$612,A32) -> 25 | C32: =B32/$B$4 -> 0.04091653
A33: NATURAL RESOURCES | B33: =COUNTIF('Final Sample'!$E$2:$E$612,A33) -> 10 | C33: =B33/$B$4 -> 0.016366612
A34: Total | B34: =SUM(B21:B33) -> 611 | C34: =SUM(C21:C33) -> 1
A36: Note: sector order ranked by mean SDQ_Score, high to low (see Table 4, '4. Sector Breakdown' tab).
A37: Source: Final Sample tab, this workbook. All counts computed via COUNTIF referencing the underlying 611 firm-year rows.

Sheet 2. SDQ CDQ Descriptives
A1: TABLE 2: DESCRIPTIVE STATISTICS - SDQ AND CDQ
A2: Answers Objective 1 / Research Question 1 directly
A4: Statistic | B4: SDQ_Score (0-100) | C4: CDQ_Score (0-100)
A5: N | B5: =COUNT('Final Sample'!$I$2:$I$612) -> 611 | C5: =COUNT('Final Sample'!$J$2:$J$612) -> 611
A6: Mean | B6: =AVERAGE('Final Sample'!$I$2:$I$612) -> 13.151255 | C6: =AVERAGE('Final Sample'!$J$2:$J$612) -> 6.3702492
A7: Median | B7: =MEDIAN('Final Sample'!$I$2:$I$612) -> 0 | C7: =MEDIAN('Final Sample'!$J$2:$J$612) -> 0
A8: Std. Deviation | B8: =STDEV('Final Sample'!$I$2:$I$612) -> 22.15489 | C8: =STDEV('Final Sample'!$J$2:$J$612) -> 18.035558
A9: Minimum | B9: =MIN('Final Sample'!$I$2:$I$612) -> 0 | C9: =MIN('Final Sample'!$J$2:$J$612) -> 0
A10: Maximum | B10: =MAX('Final Sample'!$I$2:$I$612) -> 95 | C10: =MAX('Final Sample'!$J$2:$J$612) -> 93.333333
A11: Skewness | B11: =SKEW('Final Sample'!$I$2:$I$612) -> 1.8657522 | C11: =SKEW('Final Sample'!$J$2:$J$612) -> 3.2480117
A12: Kurtosis (excess) | B12: =KURT('Final Sample'!$I$2:$I$612) -> 2.7133722 | C12: =KURT('Final Sample'!$J$2:$J$612) -> 10.057378
A13: Shapiro-Wilk W | B13: 0.6596 | C13: 0.4067
A14: Shapiro-Wilk p-value | B14: 3.8216813e-33 | C14: 1.4295345e-40
A16: Interpretation:
A17: Both indices depart sharply from normality (p < .001 in both cases). Median SDQ and CDQ are both 0.00, meaning more than half of firm-years in the sample disclose against none of the coded items, while mean SDQ (13.15) and mean CDQ (6.37) sit well above the median, pulled up by a smaller group of high-disclosing firms. This right-skew, floor-loaded shape is why Spearman correlation and the Mann-Whitney U / Kruskal-Wallis tests (not Pearson correlation or ANOVA / independent t-test) are used throughout the remaining analysis, consistent with the fallback already specified in Chapter Three.
A19: Note: Shapiro-Wilk W and p-value computed via SciPy (scipy.stats.shapiro) — Excel/SPSS Statistics has no native worksheet function for this test. All other statistics above are live Excel formulas referencing the Final Sample tab and will recompute if the underlying data changes. To replicate the Shapiro-Wilk result in SPSS: Analyze > Descriptive Statistics > Explore > Plots > Normality plots with tests.

Sheet 3. Trend by Year
A1: TABLE 3: SDQ / CDQ TREND, 2021-2025
A2: Is disclosure quality improving over the study window? Tested via firm fixed-effects regression, not between-year comparison (see Part 2 below).
A4: Year | B4: N | C4: Mean SDQ | D4: SD SDQ | E4: Mean CDQ | F4: SD CDQ
A5: 2021 | B5: =COUNTIF('Final Sample'!$F$2:$F$612,A5) -> 118 | C5: =AVERAGEIF('Final Sample'!$F$2:$F$612,A5,'Final Sample'!$I$2:$I$612) -> 9.6186441 | D5: =SQRT(SUMPRODUCT(('Final Sample'!$F$2:$F$612=A5)*('Final Sample'!$I$2:$I$612-AVERAGEIF('Final Sample'!$F$2:$F$612,A5,'Final Sample'!$I$2:$I$612))^2)/(COUNTIF('Final Sample'!$F$2:$F$612,A5)-1)) -> 16.655853 | E5: =AVERAGEIF('Final Sample'!$F$2:$F$612,A5,'Final Sample'!$J$2:$J$612) -> 3.3333333 | F5: =SQRT(SUMPRODUCT(('Final Sample'!$F$2:$F$612=A5)*('Final Sample'!$J$2:$J$612-AVERAGEIF('Final Sample'!$F$2:$F$612,A5,'Final Sample'!$J$2:$J$612))^2)/(COUNTIF('Final Sample'!$F$2:$F$612,A5)-1)) -> 12.038242
A6: 2022 | B6: =COUNTIF('Final Sample'!$F$2:$F$612,A6) -> 122 | C6: =AVERAGEIF('Final Sample'!$F$2:$F$612,A6,'Final Sample'!$I$2:$I$612) -> 12.377049 | D6: =SQRT(SUMPRODUCT(('Final Sample'!$F$2:$F$612=A6)*('Final Sample'!$I$2:$I$612-AVERAGEIF('Final Sample'!$F$2:$F$612,A6,'Final Sample'!$I$2:$I$612))^2)/(COUNTIF('Final Sample'!$F$2:$F$612,A6)-1)) -> 20.970395 | E6: =AVERAGEIF('Final Sample'!$F$2:$F$612,A6,'Final Sample'!$J$2:$J$612) -> 5.3551913 | F6: =SQRT(SUMPRODUCT(('Final Sample'!$F$2:$F$612=A6)*('Final Sample'!$J$2:$J$612-AVERAGEIF('Final Sample'!$F$2:$F$612,A6,'Final Sample'!$J$2:$J$612))^2)/(COUNTIF('Final Sample'!$F$2:$F$612,A6)-1)) -> 16.049495
A7: 2023 | B7: =COUNTIF('Final Sample'!$F$2:$F$612,A7) -> 122 | C7: =AVERAGEIF('Final Sample'!$F$2:$F$612,A7,'Final Sample'!$I$2:$I$612) -> 12.868852 | D7: =SQRT(SUMPRODUCT(('Final Sample'!$F$2:$F$612=A7)*('Final Sample'!$I$2:$I$612-AVERAGEIF('Final Sample'!$F$2:$F$612,A7,'Final Sample'!$I$2:$I$612))^2)/(COUNTIF('Final Sample'!$F$2:$F$612,A7)-1)) -> 22.424511 | E7: =AVERAGEIF('Final Sample'!$F$2:$F$612,A7,'Final Sample'!$J$2:$J$612) -> 7.1584699 | F7: =SQRT(SUMPRODUCT(('Final Sample'!$F$2:$F$612=A7)*('Final Sample'!$J$2:$J$612-AVERAGEIF('Final Sample'!$F$2:$F$612,A7,'Final Sample'!$J$2:$J$612))^2)/(COUNTIF('Final Sample'!$F$2:$F$612,A7)-1)) -> 19.864889
A8: 2024 | B8: =COUNTIF('Final Sample'!$F$2:$F$612,A8) -> 125 | C8: =AVERAGEIF('Final Sample'!$F$2:$F$612,A8,'Final Sample'!$I$2:$I$612) -> 15.826667 | D8: =SQRT(SUMPRODUCT(('Final Sample'!$F$2:$F$612=A8)*('Final Sample'!$I$2:$I$612-AVERAGEIF('Final Sample'!$F$2:$F$612,A8,'Final Sample'!$I$2:$I$612))^2)/(COUNTIF('Final Sample'!$F$2:$F$612,A8)-1)) -> 24.72757 | E8: =AVERAGEIF('Final Sample'!$F$2:$F$612,A8,'Final Sample'!$J$2:$J$612) -> 7.9288891 | F8: =SQRT(SUMPRODUCT(('Final Sample'!$F$2:$F$612=A8)*('Final Sample'!$J$2:$J$612-AVERAGEIF('Final Sample'!$F$2:$F$612,A8,'Final Sample'!$J$2:$J$612))^2)/(COUNTIF('Final Sample'!$F$2:$F$612,A8)-1)) -> 20.848845
A9: 2025 | B9: =COUNTIF('Final Sample'!$F$2:$F$612,A9) -> 124 | C9: =AVERAGEIF('Final Sample'!$F$2:$F$612,A9,'Final Sample'!$I$2:$I$612) -> 14.855511 | D9: =SQRT(SUMPRODUCT(('Final Sample'!$F$2:$F$612=A9)*('Final Sample'!$I$2:$I$612-AVERAGEIF('Final Sample'!$F$2:$F$612,A9,'Final Sample'!$I$2:$I$612))^2)/(COUNTIF('Final Sample'!$F$2:$F$612,A9)-1)) -> 24.572282 | E9: =AVERAGEIF('Final Sample'!$F$2:$F$612,A9,'Final Sample'!$J$2:$J$612) -> 7.9121866 | F9: =SQRT(SUMPRODUCT(('Final Sample'!$F$2:$F$612=A9)*('Final Sample'!$J$2:$J$612-AVERAGEIF('Final Sample'!$F$2:$F$612,A9,'Final Sample'!$J$2:$J$612))^2)/(COUNTIF('Final Sample'!$F$2:$F$612,A9)-1)) -> 19.498167
A11: FIRM FIXED-EFFECTS TREND REGRESSION (2021-2025)
A12: Model: Score_it = alpha_i + beta*Year_c_it + e_it, entity (firm) fixed effects, standard errors clustered by firm. Year_c = Year - 2021 (0 to 4). Replaces the between-year Kruskal-Wallis test, which is not appropriate for repeated firm-year panel data (see notes below).
A14: Variable | B14: Coefficient (per year) | C14: Clustered SE | D14: t-statistic | E14: p-value | F14: Within R-sq.
A15: SDQ_Score | B15: 1.479 | C15: 0.5343 | D15: 2.768 | E15: 0.0056 | F15: 0.038
A16: CDQ_Score | B16: 1.2863 | C16: 0.3868 | D16: 3.325 | E16: 0.0009 | F16: 0.046
A18: N = 611 firm-years, 128 firms
A20: Both indices show a statistically significant within-firm upward trend once firm fixed effects isolate genuine change over time from between-firm heterogeneity: SDQ rises 1.48 points per year (p=.006), CDQ rises 1.29 points per year (p<.001). This is the methodologically appropriate test for this data: SDQ_Score and CDQ_Score are repeated observations on the same 128 firms across 5 years, not independent cross-sections, so a between-year comparison (Kruskal-Wallis or ANOVA) mixes real within-firm improvement with persistent between-firm differences (a consistently high-disclosing bank sitting next to a consistently zero-disclosing firm every year looks like 'no trend' to a between-group test even when every firm individually improves). The fixed-effects specification removes that confound. Within R-squared (3.8% for SDQ, 4.6% for CDQ) confirms the effect is real but modest in magnitude, time alone explains a small share of within-firm variation; other factors (firm-specific events, sector shifts, individual reporting decisions) account for the rest.
A22: Method and citation: entity fixed-effects with firm-clustered standard errors, following Petersen, M. A. (2009), 'Estimating Standard Errors in Finance Panel Data Sets: Comparing Approaches,' The Review of Financial Studies, 22(1), 435-480, https://doi.org/10.1093/rfs/hhn053, the standard reference for handling within-firm serial correlation in accounting/finance panel data. This is the same fixed-effects framework used for Objectives 2 and 3 (selected via the Hausman test, Hausman, J. A., 1978, 'Specification Tests in Econometrics,' Econometrica, 46(6), 1251-1271), applied here to the trend question ahead of the main regressions. Computed via Python (statsmodels: entity-demeaned OLS for the within R-squared; least-squares dummy variable regression with cluster-robust covariance for the coefficient, SE, and p-value, both give the same point estimate). Replicate in R via plm(..., model='within', effect='individual') with vcovHC(..., cluster='group') from the plm/sandwich packages, consistent with the R/plm toolset already specified in Chapter Three for Objectives 2 and 3.

Sheet 4. Sector Breakdown
A1: TABLE 4: SDQ / CDQ BY SECTOR
A2: Ranked by mean SDQ_Score, high to low
A4: Sector | B4: N | C4: Mean SDQ | D4: SD SDQ | E4: Mean CDQ | F4: SD CDQ
A5: OIL AND GAS | B5: =COUNTIF('Final Sample'!$E$2:$E$612,A5) -> 32 | C5: =AVERAGEIF('Final Sample'!$E$2:$E$612,A5,'Final Sample'!$I$2:$I$612) -> 23.59375 | D5: =IFERROR(SQRT(SUMPRODUCT(('Final Sample'!$E$2:$E$612=A5)*('Final Sample'!$I$2:$I$612-AVERAGEIF('Final Sample'!$E$2:$E$612,A5,'Final Sample'!$I$2:$I$612))^2)/(COUNTIF('Final Sample'!$E$2:$E$612,A5)-1)),0) -> 26.94781 | E5: =AVERAGEIF('Final Sample'!$E$2:$E$612,A5,'Final Sample'!$J$2:$J$612) -> 13.958333 | F5: =IFERROR(SQRT(SUMPRODUCT(('Final Sample'!$E$2:$E$612=A5)*('Final Sample'!$J$2:$J$612-AVERAGEIF('Final Sample'!$E$2:$E$612,A5,'Final Sample'!$J$2:$J$612))^2)/(COUNTIF('Final Sample'!$E$2:$E$612,A5)-1)),0) -> 26.524318
A6: FINANCIAL SERVICES | B6: =COUNTIF('Final Sample'!$E$2:$E$612,A6) -> 196 | C6: =AVERAGEIF('Final Sample'!$E$2:$E$612,A6,'Final Sample'!$I$2:$I$612) -> 17.357568 | D6: =IFERROR(SQRT(SUMPRODUCT(('Final Sample'!$E$2:$E$612=A6)*('Final Sample'!$I$2:$I$612-AVERAGEIF('Final Sample'!$E$2:$E$612,A6,'Final Sample'!$I$2:$I$612))^2)/(COUNTIF('Final Sample'!$E$2:$E$612,A6)-1)),0) -> 25.573447 | E6: =AVERAGEIF('Final Sample'!$E$2:$E$612,A6,'Final Sample'!$J$2:$J$612) -> 8.7131517 | F6: =IFERROR(SQRT(SUMPRODUCT(('Final Sample'!$E$2:$E$612=A6)*('Final Sample'!$J$2:$J$612-AVERAGEIF('Final Sample'!$E$2:$E$612,A6,'Final Sample'!$J$2:$J$612))^2)/(COUNTIF('Final Sample'!$E$2:$E$612,A6)-1)),0) -> 21.6876
A7: HEALTHCARE | B7: =COUNTIF('Final Sample'!$E$2:$E$612,A7) -> 23 | C7: =AVERAGEIF('Final Sample'!$E$2:$E$612,A7,'Final Sample'!$I$2:$I$612) -> 17.173913 | D7: =IFERROR(SQRT(SUMPRODUCT(('Final Sample'!$E$2:$E$612=A7)*('Final Sample'!$I$2:$I$612-AVERAGEIF('Final Sample'!$E$2:$E$612,A7,'Final Sample'!$I$2:$I$612))^2)/(COUNTIF('Final Sample'!$E$2:$E$612,A7)-1)),0) -> 19.058885 | E7: =AVERAGEIF('Final Sample'!$E$2:$E$612,A7,'Final Sample'!$J$2:$J$612) -> 3.7681159 | F7: =IFERROR(SQRT(SUMPRODUCT(('Final Sample'!$E$2:$E$612=A7)*('Final Sample'!$J$2:$J$612-AVERAGEIF('Final Sample'!$E$2:$E$612,A7,'Final Sample'!$J$2:$J$612))^2)/(COUNTIF('Final Sample'!$E$2:$E$612,A7)-1)),0) -> 7.7397275
A8: CONSUMER GOODS | B8: =COUNTIF('Final Sample'!$E$2:$E$612,A8) -> 79 | C8: =AVERAGEIF('Final Sample'!$E$2:$E$612,A8,'Final Sample'!$I$2:$I$612) -> 16.518987 | D8: =IFERROR(SQRT(SUMPRODUCT(('Final Sample'!$E$2:$E$612=A8)*('Final Sample'!$I$2:$I$612-AVERAGEIF('Final Sample'!$E$2:$E$612,A8,'Final Sample'!$I$2:$I$612))^2)/(COUNTIF('Final Sample'!$E$2:$E$612,A8)-1)),0) -> 20.370832 | E8: =AVERAGEIF('Final Sample'!$E$2:$E$612,A8,'Final Sample'!$J$2:$J$612) -> 6.0759494 | F8: =IFERROR(SQRT(SUMPRODUCT(('Final Sample'!$E$2:$E$612=A8)*('Final Sample'!$J$2:$J$612-AVERAGEIF('Final Sample'!$E$2:$E$612,A8,'Final Sample'!$J$2:$J$612))^2)/(COUNTIF('Final Sample'!$E$2:$E$612,A8)-1)),0) -> 13.76191
A9: ICT | B9: =COUNTIF('Final Sample'!$E$2:$E$612,A9) -> 41 | C9: =AVERAGEIF('Final Sample'!$E$2:$E$612,A9,'Final Sample'!$I$2:$I$612) -> 15.609756 | D9: =IFERROR(SQRT(SUMPRODUCT(('Final Sample'!$E$2:$E$612=A9)*('Final Sample'!$I$2:$I$612-AVERAGEIF('Final Sample'!$E$2:$E$612,A9,'Final Sample'!$I$2:$I$612))^2)/(COUNTIF('Final Sample'!$E$2:$E$612,A9)-1)),0) -> 31.428393 | E9: =AVERAGEIF('Final Sample'!$E$2:$E$612,A9,'Final Sample'!$J$2:$J$612) -> 15.284553 | F9: =IFERROR(SQRT(SUMPRODUCT(('Final Sample'!$E$2:$E$612=A9)*('Final Sample'!$J$2:$J$612-AVERAGEIF('Final Sample'!$E$2:$E$612,A9,'Final Sample'!$J$2:$J$612))^2)/(COUNTIF('Final Sample'!$E$2:$E$612,A9)-1)),0) -> 30.740632
A10: INDUSTRIAL GOODS | B10: =COUNTIF('Final Sample'!$E$2:$E$612,A10) -> 59 | C10: =AVERAGEIF('Final Sample'!$E$2:$E$612,A10,'Final Sample'!$I$2:$I$612) -> 13.954803 | D10: =IFERROR(SQRT(SUMPRODUCT(('Final Sample'!$E$2:$E$612=A10)*('Final Sample'!$I$2:$I$612-AVERAGEIF('Final Sample'!$E$2:$E$612,A10,'Final Sample'!$I$2:$I$612))^2)/(COUNTIF('Final Sample'!$E$2:$E$612,A10)-1)),0) -> 21.542302 | E10: =AVERAGEIF('Final Sample'!$E$2:$E$612,A10,'Final Sample'!$J$2:$J$612) -> 7.6459525 | F10: =IFERROR(SQRT(SUMPRODUCT(('Final Sample'!$E$2:$E$612=A10)*('Final Sample'!$J$2:$J$612-AVERAGEIF('Final Sample'!$E$2:$E$612,A10,'Final Sample'!$J$2:$J$612))^2)/(COUNTIF('Final Sample'!$E$2:$E$612,A10)-1)),0) -> 17.070568
A11: AGRICULTURE | B11: =COUNTIF('Final Sample'!$E$2:$E$612,A11) -> 25 | C11: =AVERAGEIF('Final Sample'!$E$2:$E$612,A11,'Final Sample'!$I$2:$I$612) -> 10.4 | D11: =IFERROR(SQRT(SUMPRODUCT(('Final Sample'!$E$2:$E$612=A11)*('Final Sample'!$I$2:$I$612-AVERAGEIF('Final Sample'!$E$2:$E$612,A11,'Final Sample'!$I$2:$I$612))^2)/(COUNTIF('Final Sample'!$E$2:$E$612,A11)-1)),0) -> 17.907168 | E11: =AVERAGEIF('Final Sample'!$E$2:$E$612,A11,'Final Sample'!$J$2:$J$612) -> 0 | F11: =IFERROR(SQRT(SUMPRODUCT(('Final Sample'!$E$2:$E$612=A11)*('Final Sample'!$J$2:$J$612-AVERAGEIF('Final Sample'!$E$2:$E$612,A11,'Final Sample'!$J$2:$J$612))^2)/(COUNTIF('Final Sample'!$E$2:$E$612,A11)-1)),0) -> 0
A12: CONSTRUCTION/REAL ESTATE | B12: =COUNTIF('Final Sample'!$E$2:$E$612,A12) -> 17 | C12: =AVERAGEIF('Final Sample'!$E$2:$E$612,A12,'Final Sample'!$I$2:$I$612) -> 10 | D12: =IFERROR(SQRT(SUMPRODUCT(('Final Sample'!$E$2:$E$612=A12)*('Final Sample'!$I$2:$I$612-AVERAGEIF('Final Sample'!$E$2:$E$612,A12,'Final Sample'!$I$2:$I$612))^2)/(COUNTIF('Final Sample'!$E$2:$E$612,A12)-1)),0) -> 18.624581 | E12: =AVERAGEIF('Final Sample'!$E$2:$E$612,A12,'Final Sample'!$J$2:$J$612) -> 4.7058824 | F12: =IFERROR(SQRT(SUMPRODUCT(('Final Sample'!$E$2:$E$612=A12)*('Final Sample'!$J$2:$J$612-AVERAGEIF('Final Sample'!$E$2:$E$612,A12,'Final Sample'!$J$2:$J$612))^2)/(COUNTIF('Final Sample'!$E$2:$E$612,A12)-1)),0) -> 7.7332995
A13: UTILITIES | B13: =COUNTIF('Final Sample'!$E$2:$E$612,A13) -> 6 | C13: =AVERAGEIF('Final Sample'!$E$2:$E$612,A13,'Final Sample'!$I$2:$I$612) -> 8.3333333 | D13: =IFERROR(SQRT(SUMPRODUCT(('Final Sample'!$E$2:$E$612=A13)*('Final Sample'!$I$2:$I$612-AVERAGEIF('Final Sample'!$E$2:$E$612,A13,'Final Sample'!$I$2:$I$612))^2)/(COUNTIF('Final Sample'!$E$2:$E$612,A13)-1)),0) -> 15.705625 | E13: =AVERAGEIF('Final Sample'!$E$2:$E$612,A13,'Final Sample'!$J$2:$J$612) -> 0 | F13: =IFERROR(SQRT(SUMPRODUCT(('Final Sample'!$E$2:$E$612=A13)*('Final Sample'!$J$2:$J$612-AVERAGEIF('Final Sample'!$E$2:$E$612,A13,'Final Sample'!$J$2:$J$612))^2)/(COUNTIF('Final Sample'!$E$2:$E$612,A13)-1)),0) -> 0
A14: INVESTMENT | B14: =COUNTIF('Final Sample'!$E$2:$E$612,A14) -> 3 | C14: =AVERAGEIF('Final Sample'!$E$2:$E$612,A14,'Final Sample'!$I$2:$I$612) -> 3.3333333 | D14: =IFERROR(SQRT(SUMPRODUCT(('Final Sample'!$E$2:$E$612=A14)*('Final Sample'!$I$2:$I$612-AVERAGEIF('Final Sample'!$E$2:$E$612,A14,'Final Sample'!$I$2:$I$612))^2)/(COUNTIF('Final Sample'!$E$2:$E$612,A14)-1)),0) -> 2.8867513 | E14: =AVERAGEIF('Final Sample'!$E$2:$E$612,A14,'Final Sample'!$J$2:$J$612) -> 0 | F14: =IFERROR(SQRT(SUMPRODUCT(('Final Sample'!$E$2:$E$612=A14)*('Final Sample'!$J$2:$J$612-AVERAGEIF('Final Sample'!$E$2:$E$612,A14,'Final Sample'!$J$2:$J$612))^2)/(COUNTIF('Final Sample'!$E$2:$E$612,A14)-1)),0) -> 0
