Workbook

Sheet Coding Instrument
A1: SDQ / CDQ CODING INSTRUMENT
A2: Sustainability Disclosure Quality (SDQ) and Climate-related Disclosure Quality (CDQ) content-analysis checklist
A3: Derived from IFRS S1 (four pillars: Governance, Strategy, Risk Management, Metrics & Targets) and IFRS S2 (climate-specific items across the same four pillars)
A5: HOW TO USE THIS INSTRUMENT
A6: 1. This tab defines every item scored in the 'Coding Sheet' tab. Score each item 1 (disclosed) or 0 (not disclosed) per firm-year.
A7: 2. Score against the firm's annual report, standalone sustainability report and integrated report for that specific fiscal year - the same documents used for the financial data.
A8: 3. A '1' requires entity-specific, substantive disclosure. Generic boilerplate ('we are committed to sustainability') without specifics scores 0.
A9: 4. SDQ_Score = (sum of 20 SDQ items disclosed / 20) x 100. CDQ_Score = (sum of 15 CDQ items disclosed / 15) x 100. Both computed automatically in the Coding Sheet.
A10: 5. Record the source document and page/section for each firm-year in the Coding_Notes column of the Coding Sheet - this is your audit trail for Chapter Three's reliability discussion.
A11: 6. Recommended reliability check: after scoring roughly 10% of firm-years, recode a random sample of them without looking at your first pass, then compare agreement. Report this in Chapter Three.
A13: WORKED EXAMPLE (illustrative only - not a real firm)
A14: Item SDQ_M1 (metric disclosed): A firm's sustainability report states 'we monitor several environmental indicators across our operations' -> score 0 (no named metric). A different firm states 'total water withdrawal was 482,000 cubic metres in FY2024, down from 511,000 in FY2023' -> score 1 (specific, entity-level metric with a figure).
A16: Code | B16: Pillar
A17: SUSTAINABILITY DISCLOSURE QUALITY (SDQ) - IFRS S1, 20 items
A18: SDQ_G1 | B18: Governance | C18: Board-level oversight of sustainability-related risks and opportunities is described (which committee/body, and how oversight is exercised) | D18: 1 if the firm names a specific board/committee role and describes its oversight activity; 0 if only a generic statement that 'the board oversees sustainability'
A19: SDQ_G2 | B19: Governance | C19: Management's role in assessing and managing sustainability-related risks and opportunities is described (which role/officer, delegated authority) | D19: 1 if a specific management role or function is named with responsibilities; 0 if absent or vague
A20: SDQ_G3 | B20: Governance | C20: Processes and frequency by which the board is informed of sustainability-related matters are disclosed | D20: 1 if a reporting frequency or defined process is stated; 0 if not mentioned
A21: SDQ_G4 | B21: Governance | C21: Whether/how sustainability-related performance is reflected in board or executive oversight mechanisms (e.g. review of targets, sustainability committee minutes referenced) | D21: 1 if a concrete oversight mechanism is described; 0 if absent
A22: SDQ_G5 | B22: Governance | C22: Skills, competencies or expertise relevant to sustainability oversight held by the board or those charged with governance are disclosed | D22: 1 if specific expertise/training is named; 0 if absent
A23: SDQ_S1 | B23: Strategy | C23: Sustainability-related risks and opportunities the entity has identified over short, medium and long term are described | D23: 1 if specific risks/opportunities are named (not generic ESG language); 0 otherwise
A24: SDQ_S2 | B24: Strategy | C24: Effects of sustainability-related risks and opportunities on the business model and value chain are described | D24: 1 if a specific effect on operations/value chain is discussed; 0 if absent
A25: SDQ_S3 | B25: Strategy | C25: Effects of sustainability-related risks and opportunities on strategy and decision-making are described | D25: 1 if strategic responses are named; 0 if absent
A26: SDQ_S4 | B26: Strategy | C26: Effects on financial position, financial performance and cash flows (current or anticipated) are disclosed | D26: 1 if a financial effect, even qualitative, is quantified or specifically described; 0 if absent
A27: SDQ_S5 | B27: Strategy | C27: Resilience of the strategy to sustainability-related risks is discussed (qualitative or scenario-based) | D27: 1 if any resilience assessment or scenario discussion appears; 0 if absent
A28: SDQ_R1 | B28: Risk Management | C28: Processes for identifying sustainability-related risks are described | D28: 1 if a specific process/methodology is named; 0 if absent
A29: SDQ_R2 | B29: Risk Management | C29: Processes for assessing and prioritising sustainability-related risks are described | D29: 1 if criteria for assessment/prioritisation are named; 0 if absent
A30: SDQ_R3 | B30: Risk Management | C30: Processes for monitoring sustainability-related risks are described | D30: 1 if an ongoing monitoring process is named; 0 if absent
A31: SDQ_R4 | B31: Risk Management | C31: Integration of sustainability risk management into the entity's overall enterprise risk management is disclosed | D31: 1 if the disclosure explicitly states integration with ERM; 0 if silent or only implied | F31: 25569
A32: SDQ_R5 | B32: Risk Management | C32: Processes for identifying sustainability-related opportunities are described | D32: 1 if a specific process is named; 0 if absent
A33: SDQ_M1 | B33: Metrics and Targets | C33: Metrics used to measure and monitor sustainability-related performance are disclosed | D33: 1 if at least one named, entity-specific metric is disclosed; 0 if only narrative with no metric
A34: SDQ_M2 | B34: Metrics and Targets | C34: Targets set for sustainability-related performance, and progress against those targets, are disclosed | D34: 1 if a specific target and progress figure/status are both given; 0 if either is missing
A35: SDQ_M3 | B35: Metrics and Targets | C35: Industry-based or cross-industry metrics relevant to the entity's sector are disclosed | D35: 1 if sector-relevant metrics beyond generic ESG figures appear; 0 if absent
A36: SDQ_M4 | B36: Metrics and Targets | C36: Remuneration is linked, in whole or part, to sustainability-related targets or performance | D36: 1 if explicitly stated; 0 if absent or not disclosed
A37: SDQ_M5 | B37: Metrics and Targets | C37: Methodology or basis used to calculate the disclosed metrics is explained | D37: 1 if a calculation basis/standard is named; 0 if figures are given with no stated methodology
A39: CLIMATE-RELATED DISCLOSURE QUALITY (CDQ) - IFRS S2, 15 items
A40: CDQ_G1 | B40: Climate Governance | C40: Board-level oversight specifically of climate-related risks and opportunities is described | D40: 1 if climate oversight is distinguished from general sustainability oversight; 0 if only generic sustainability governance is described
A41: CDQ_G2 | B41: Climate Governance | C41: Management's role in assessing and managing climate-related risks and opportunities is described | D41: 1 if a specific role/officer is named; 0 if absent
A42: CDQ_G3 | B42: Climate Governance | C42: Climate-related skills or expertise represented at board or management level are disclosed | D42: 1 if specific climate expertise/training is named; 0 if absent
A43: CDQ_S1 | B43: Climate Strategy | C43: Climate-related risks and opportunities are described, distinguishing physical risk from transition risk | D43: 1 if both physical and transition risk are addressed; 0 if only one or neither is addressed
A44: CDQ_S2 | B44: Climate Strategy | C44: Effects of climate-related risks and opportunities on the business model and value chain are described | D44: 1 if a specific effect is discussed; 0 if absent
...

Sheet Coding Sheet
A1: Key | B1: S/N | C1: Firm_ID | D1: Ticker | E1: Company Name | F1: Sector | G1: Year | H1: SDQ_G1 | I1: SDQ_G2 | J1: SDQ_G3 | K1: SDQ_G4 | L1: SDQ_G5 | M1: SDQ_S1 | N1: SDQ_S2 | O1: SDQ_S3 | P1: SDQ_S4 | Q1: SDQ_S5 | R1: SDQ_R1 | S1: SDQ_R2 | T1: SDQ_R3 | U1: SDQ_R4 | V1: SDQ_R5 | W1: SDQ_M1 | X1: SDQ_M2 | Y1: SDQ_M3 | Z1: SDQ_M4 | AA1: SDQ_M5 | AB1: SDQ_Items_Disclosed (of 20) | AC1: SDQ_Score (0-100) | AD1: CDQ_G1 | AE1: CDQ_G2 | AF1: CDQ_G3 | AG1: CDQ_S1 | AH1: CDQ_S2 | AI1: CDQ_S3 | AJ1: CDQ_S4 | AK1: CDQ_R1 | AL1: CDQ_R2 | AM1: CDQ_M1 | AN1: CDQ_M2 | AO1: CDQ_M3 | AP1: CDQ_M4 | AQ1: CDQ_M5 | AR1: CDQ_M6 | AS1: CDQ_Items_Disclosed (of 15) | AT1: CDQ_Score (0-100) | AU1: Coding_Notes / Source (document, page/section per firm-year)
A2: =C2&"_"&G2 -> 1_2021 | B2: 1 | C2: ='Panel Data (Long Format)'!B2 -> 1 | D2: ='Panel Data (Long Format)'!C2 -> ABBEYBANK | E2: ='Panel Data (Long Format)'!D2 -> Abbey Mortgage Bank Plc | F2: ='Panel Data (Long Format)'!E2 -> FINANCIAL SERVICES | G2: ='Panel Data (Long Format)'!F2 -> 2021 | H2: 0 | I2: 0 | J2: 0 | K2: 0 | L2: 0 | M2: 0 | N2: 0 | O2: 0 | P2: 0 | Q2: 0 | R2: 0 | S2: 0 | T2: 0 | U2: 0 | V2: 0 | W2: 1 | X2: 0 | Y2: 0 | Z2: 0 | AA2: 0 | AB2: =IF(COUNTBLANK(H2:AA2)>0,"",SUM(H2:AA2)) -> 1 | AC2: =IF(AB2="","",AB2/20*100) -> 5 | AD2: 0 | AE2: 0 | AF2: 0 | AG2: 0 | AH2: 0 | AI2: 0 | AJ2: 0 | AK2: 0 | AL2: 0 | AM2: 0 | AN2: 0 | AO2: 0 | AP2: 0 | AQ2: 0 | AR2: 0 | AS2: =IF(COUNTBLANK(AD2:AR2)>0,"",SUM(AD2:AR2)) -> 0 | AT2: =IF(AS2="","",AS2/15*100) -> 0 | AU2: Abbey Mortgage Bank Plc, Annual Report & Accounts FYE 31-Dec-2021 (Corporate Governance Report pp.33-38, Enterprise Risk Management Policy pp.42-46, Report of the Directors substantial-interest note p.premier). Source: anyflip.com/jfssr/cyis (Abbey Annual Report Final 2021_compressed), full text extracted and read. Board FY2021: Non-Executive Chairman + 4 NEDs + 3 EDs + 1 Independent NED = 9 total. SDQ_G5=0 (unlike FY2024): Ms. Jewel Okwechime, whose bio carries explicit environmental/sustainability credentials, was NOT yet on the board in FY2021 (absent from the FY2021 committee/EXCO membership lists) -- her appointment came later. SDQ_M1=1 (BORDERLINE, same as FY2024, flag for reliability recheck): 'last year there were no recorded cases of incidents in our operations' -- identical boilerplate to the FY2024 filing. All SDQ_R1-R5=0 and all CDQ=0: the FY2021 Enterprise Risk Management Policy lists the identical 9 risk categories as FY2024 (credit, liquidity, capital, operational, regulatory, reputational, legal, cyber, strategic) with no sustainability/ESG/climate risk category named anywhere; full-text keyword search for IFRS S1/S2, ISSB, Scope 1/2/3, GHG/carbon/emissions, scenario analysis, transition/physical risk returned zero matches. IFRS_S1S2_Adopter_Dummy=0 (no explicit or implied statement; CDQ=0/15 so the structural-alignment test also fails). SDQ=1/20=5%, CDQ=0/15=0%.
A3: =C3&"_"&G3 -> 1_2022 | B3: 2 | C3: ='Panel Data (Long Format)'!B3 -> 1 | D3: ='Panel Data (Long Format)'!C3 -> ABBEYBANK | E3: ='Panel Data (Long Format)'!D3 -> Abbey Mortgage Bank Plc | F3: ='Panel Data (Long Format)'!E3 -> FINANCIAL SERVICES | G3: ='Panel Data (Long Format)'!F3 -> 2022 | H3: 0 | I3: 0 | J3: 0 | K3: 0 | L3: 0 | M3: 0 | N3: 0 | O3: 0 | P3: 0 | Q3: 0 | R3: 0 | S3: 0 | T3: 0 | U3: 0 | V3: 0 | W3: 0 | X3: 0 | Y3: 0 | Z3: 0 | AA3: 0 | AB3: =IF(COUNTBLANK(H3:AA3)>0,"",SUM(H3:AA3)) -> 0 | AC3: =IF(AB3="","",AB3/20*100) -> 0 | AD3: 0 | AE3: 0 | AF3: 0 | AG3: 0 | AH3: 0 | AI3: 0 | AJ3: 0 | AK3: 0 | AL3: 0 | AM3: 0 | AN3: 0 | AO3: 0 | AP3: 0 | AQ3: 0 | AR3: 0 | AS3: =IF(COUNTBLANK(AD3:AR3)>0,"",SUM(AD3:AR3)) -> 0 | AT3: =IF(AS3="","",AS3/15*100) -> 0 | AU3: Abbey Mortgage Bank Plc, Annual Report & Audited FS FYE 31-Dec-2022 (NGX doclib doc #38233, filed Apr-2023). Corporate Governance Report pp.11-19 (board/committee structure named, no sustainability-specific oversight); 'Sustainable and Environmental Issues'/CSR section pp.17-18 (generic OH&S boilerplate, no entity-specific metrics/targets); Enterprise Risk Management Policy pp.21-25 (risk taxonomy = credit/capital/operational/liquidity/IT/regulatory/legal/reputational/strategic only, no sustainability/climate risk category); Notes to FS 'Standards issued but not yet effective' p.35 discusses only IFRS 17, no IFRS S1/S2/ISSB mention (Adopter_Dummy left blank).
A4: =C4&"_"&G4 -> 1_2023 | B4: 3 | C4: ='Panel Data (Long Format)'!B4 -> 1 | D4: ='Panel Data (Long Format)'!C4 -> ABBEYBANK | E4: ='Panel Data (Long Format)'!D4 -> Abbey Mortgage Bank Plc | F4: ='Panel Data (Long Format)'!E4 -> FINANCIAL SERVICES | G4: ='Panel Data (Long Format)'!F4 -> 2023 | H4: 0 | I4: 0 | J4: 0 | K4: 0 | L4: 1 | M4: 1 | N4: 0 | O4: 0 | P4: 0 | Q4: 0 | R4: 0 | S4: 0 | T4: 0 | U4: 0 | V4: 0 | W4: 0 | X4: 0 | Y4: 0 | Z4: 0 | AA4: 0 | AB4: =IF(COUNTBLANK(H4:AA4)>0,"",SUM(H4:AA4)) -> 2 | AC4: =IF(AB4="","",AB4/20*100) -> 10 | AD4: 0 | AE4: 0 | AF4: 0 | AG4: 0 | AH4: 0 | AI4: 0 | AJ4: 0 | AK4: 0 | AL4: 0 | AM4: 0 | AN4: 0 | AO4: 0 | AP4: 0 | AQ4: 0 | AR4: 0 | AS4: =IF(COUNTBLANK(AD4:AR4)>0,"",SUM(AD4:AR4)) -> 0 | AT4: =IF(AS4="","",AS4/15*100) -> 0 | AU4: Abbey Mortgage Bank Plc, FY2023 Annual Report (anyflip.com/ukxce/clsu/basic). LIMITATION: fetch returned only a partial preview (~pp.1-50 of 154); ERM Policy, Audit Committee report and Notes to FS (incl. standards-adoption note) not retrievable, so R1-R5/M1-M5 could not be fully verified -- scores likely understate true disclosure, flagged for future re-check if full document becomes accessible. Chairman's Statement 'ESG Focus' p.24: 'We are preparing for the adoption of IFRS S1 and IFRS S2 in accordance with the road map of the FRCN and NGX' -> Adopter_Dummy=0. Directors' Profile p.18 (Ms. Jewel Okwechime, NED): competencies include 'Environmental Engineering...Sustainability Business Development' -> G5=1. MD/CEO Statement p.32: environmental risk discussion (flood/landslide, cost-vs-impact dilemma) -> S1=1.
A5: =C5&"_"&G5 -> 1_2024 | B5: 4 | C5: ='Panel Data (Long Format)'!B5 -> 1 | D5: ='Panel Data (Long Format)'!C5 -> ABBEYBANK | E5: ='Panel Data (Long Format)'!D5 -> Abbey Mortgage Bank Plc | F5: ='Panel Data (Long Format)'!E5 -> FINANCIAL SERVICES | G5: ='Panel Data (Long Format)'!F5 -> 2024 | H5: 0 | I5: 0 | J5: 0 | K5: 0 | L5: 1 | M5: 0 | N5: 0 | O5: 0 | P5: 0 | Q5: 0 | R5: 0 | S5: 0 | T5: 0 | U5: 0 | V5: 0 | W5: 1 | X5: 0 | Y5: 0 | Z5: 0 | AA5: 0 | AB5: =IF(COUNTBLANK(H5:AA5)>0,"",SUM(H5:AA5)) -> 2 | AC5: =IF(AB5="","",AB5/20*100) -> 10 | AD5: 0 | AE5: 0 | AF5: 0 | AG5: 0 | AH5: 0 | AI5: 0 | AJ5: 0 | AK5: 0 | AL5: 0 | AM5: 0 | AN5: 0 | AO5: 0 | AP5: 0 | AQ5: 0 | AR5: 0 | AS5: =IF(COUNTBLANK(AD5:AR5)>0,"",SUM(AD5:AR5)) -> 0 | AT5: =IF(AS5="","",AS5/15*100) -> 0 | AU5: Abbey Mortgage Bank Plc, Annual Report & Accounts FYE 31-Dec-2024 (Corporate Governance Report pp.10-16, Enterprise Risk Management Policy pp.18-22, Report of the Directors pp.2-5). Source: prjdg-unstruc.s3.ca-central-1.amazonaws.com (via proshare.co listing), full text extracted and read. SDQ_G5=1: Board member Ms. Jewel Okwechime's profile explicitly names 'Environmental Engineering... Sustainability Business Development' expertise and prior roles as Senior Environmental Consultant/Adviser (p.13-14) -- specific, named expertise, satisfies the item. SDQ_M1=1 (BORDERLINE, flag for reliability recheck): scored on 'last year there were no recorded cases of incidents in our operations' (p.15, H&S) -- a specific, entity-level claim with an implied zero-figure, but it is a single-year statement, not a tracked/trended metric; a stricter coder could reasonably score this 0. All SDQ_R1-R5=0: the Enterprise Risk Management Policy (pp.18-22) is thorough and names 9 risk categories (credit, liquidity, capital, operational, regulatory, reputational, legal, information/cyber, strategic) but does NOT name sustainability/ESG/climate as a risk category anywhere in the document -- the ERM items score 0 because the risk process described is not sustainability-specific, per the instrument's requirement. All CDQ items=0: no mention of IFRS S1/S2/ISSB, Scope 1/2/3, GHG/carbon/emissions, climate scenario analysis, or physical/transition risk anywhere in the document (confirmed via full-text keyword search). IFRS_S1S2_Adopter_Dummy: left BLANK (not 0) -- no explicit adoption/non-adoption statement found, unlike BUACEMENT/BUAFOODS where the filing explicitly said 'not yet adopted'; silence here is not the same as an evidenced negative. SDQ=2/20=10%, CDQ=0/15=0%.
A6: =C6&"_"&G6 -> 1_2025 | B6: 5 | C6: ='Panel Data (Long Format)'!B6 -> 1 | D6: ='Panel Data (Long Format)'!C6 -> ABBEYBANK | E6: ='Panel Data (Long Format)'!D6 -> Abbey Mortgage Bank Plc | F6: ='Panel Data (Long Format)'!E6 -> FINANCIAL SERVICES | G6: ='Panel Data (Long Format)'!F6 -> 2025 | H6: 0 | I6: 0 | J6: 0 | K6: 0 | L6: 0 | M6: 0 | N6: 0 | O6: 0 | P6: 0 | Q6: 0 | R6: 0 | S6: 0 | T6: 0 | U6: 0 | V6: 0 | W6: 0 | X6: 0 | Y6: 0 | Z6: 0 | AA6: 0 | AB6: =IF(COUNTBLANK(H6:AA6)>0,"",SUM(H6:AA6)) -> 0 | AC6: =IF(AB6="","",AB6/20*100) -> 0 | AD6: 0 | AE6: 0 | AF6: 0 | AG6: 0 | AH6: 0 | AI6: 0 | AJ6: 0 | AK6: 0 | AL6: 0 | AM6: 0 | AN6: 0 | AO6: 0 | AP6: 0 | AQ6: 0 | AR6: 0 | AS6: =IF(COUNTBLANK(AD6:AR6)>0,"",SUM(AD6:AR6)) -> 0 | AT6: =IF(AS6="","",AS6/15*100) -> 0 | AU6: Abbey Mortgage Bank Plc, FY2025 filing (NGX doclib doc #45885, filed Jan-2026) -- condensed interim-style statement only (Introduction, Result-at-a-Glance, primary statements, Notes), no Directors'/Corporate Governance/CSR/ERM section unlike full FY2022/FY2023 ARs. Notes 2.2 'Changes in accounting policies' pp.7-8 lists IFRS 16, IAS 1 (x2), IAS 7/IFRS 7, IAS 21 amendments only -- no IFRS S1/S2/ISSB mention (Adopter_Dummy blank). Full-text keyword search (sustainab/ESG/environment/climate/carbon/emission/diversity/community) = zero hits.
A7: =C7&"_"&G7 -> 2_2021 | B7: 6 | C7: ='Panel Data (Long Format)'!B7 -> 2 | D7: ='Panel Data (Long Format)'!C7 -> ABCTRANS | E7: ='Panel Data (Long Format)'!D7 -> ABC Transport Plc | F7: ='Panel Data (Long Format)'!E7 -> SERVICES | G7: ='Panel Data (Long Format)'!F7 -> 2021 | H7: 0 | I7: 0 | J7: 0 | K7: 0 | L7: 0 | M7: 0 | N7: 0 | O7: 0 | P7: 0 | Q7: 0 | R7: 0 | S7: 0 | T7: 0 | U7: 0 | V7: 0 | W7: 1 | X7: 0 | Y7: 0 | Z7: 0 | AA7: 0 | AB7: =IF(COUNTBLANK(H7:AA7)>0,"",SUM(H7:AA7)) -> 1 | AC7: =IF(AB7="","",AB7/20*100) -> 5 | AD7: 0 | AE7: 0 | AF7: 0 | AG7: 0 | AH7: 0 | AI7: 0 | AJ7: 0 | AK7: 0 | AL7: 0 | AM7: 0 | AN7: 0 | AO7: 0 | AP7: 0 | AQ7: 0 | AR7: 0 | AS7: =IF(COUNTBLANK(AD7:AR7)>0,"",SUM(AD7:AR7)) -> 0 | AT7: =IF(AS7="","",AS7/15*100) -> 0 | AU7: GAP-FILL: ABCTRANS FY2021 (FY2021 Audited Financial Statements, NGX doclib, fetched directly): SDQ_M1=1 - Directors' Report Note 10 'DONATIONS' itemises Book launch N40,000, Youth Empowerments N219,000, Corporate gifts N2,411,250, Condolences/Burial/Weddings N1,611,706, totalling N4,281,956 (labelled N'000 in the source table, though the underlying figure's scale relative to company size suggests this may actually be stated in plain Naira rather than thousands - flagged as a units ambiguity, scored as disclosed regardless per the instrument's literal rule). No sustainability-specific board committee found (Board Risk Management Committee, Corporate Governance and Remuneration Committee, Credit Risk Management Committee - all generic operational/financial remits). No climate/GHG content found. CDQ=0/15.
A8: =C8&"_"&G8 -> 2_2022 | B8: 7 | C8: ='Panel Data (Long Format)'!B8 -> 2 | D8: ='Panel Data (Long Format)'!C8 -> ABCTRANS | E8: ='Panel Data (Long Format)'!D8 -> ABC Transport Plc | F8: ='Panel Data (Long Format)'!E8 -> SERVICES | G8: ='Panel Data (Long Format)'!F8 -> 2022 | H8: 0 | I8: 0 | J8: 0 | K8: 0 | L8: 0 | M8: 0 | N8: 0 | O8: 0 | P8: 0 | Q8: 0 | R8: 0 | S8: 0 | T8: 0 | U8: 0 | V8: 0 | W8: 0 | X8: 0 | Y8: 0 | Z8: 0 | AA8: 0 | AB8: =IF(COUNTBLANK(H8:AA8)>0,"",SUM(H8:AA8)) -> 0 | AC8: =IF(AB8="","",AB8/20*100) -> 0 | AD8: 0 | AE8: 0 | AF8: 0 | AG8: 0 | AH8: 0 | AI8: 0 | AJ8: 0 | AK8: 0 | AL8: 0 | AM8: 0 | AN8: 0 | AO8: 0 | AP8: 0 | AQ8: 0 | AR8: 0 | AS8: =IF(COUNTBLANK(AD8:AR8)>0,"",SUM(AD8:AR8)) -> 0 | AT8: =IF(AS8="","",AS8/15*100) -> 0 | AU8: ABC Transport Plc, Consolidated Financial Statements FYE 31-Dec-2022 (Report of the Directors, Report of the Audit Committee -- this filing has no separate Corporate Governance Report or Enterprise Risk Management Policy section, unlike ABBEYBANK; governance/sustainability content is limited to brief paragraphs embedded in the Directors' Report). Source: doclib.ngxgroup.com (38087_ABC_TRANSPORT_PLC..._2022...pdf), full text extracted and read. All SDQ/CDQ items score 0: the Directors' Report discusses employee safety ('quarterly safety re-orientation and training programmes', 'vehicles fitted with tracking devices and speed limiters', 'accident rate...well within acceptable limits') but gives no specific figure/metric (SDQ_M1 scored 0, stricter than ABBEYBANK's 'zero incidents' claim since this is vaguer, no number at all) and no sustainability-specific governance, strategy, risk, or target content anywhere. No IFRS S1/S2/ISSB, Scope 1/2/3, GHG/carbon, or climate-scenario language found (confirmed via full-text keyword search). No 'substantial interest in shares' table or explicit Non-Executive/Independent board-composition statement found in this filing -- Board_Independence and Ownership_Concentration left blank for FY2022 (optional/opportunistic fields per agreed methodology). IFRS_S1S2_Adopter_Dummy=0 (no statement found either way in this filing; see FY2025 row for this ticker's explicit 'not yet adopted' evidence). SDQ=0/20=0%, CDQ=0/15=0%.
A9: =C9&"_"&G9 -> 2_2023 | B9: 8 | C9: ='Panel Data (Long Format)'!B9 -> 2 | D9: ='Panel Data (Long Format)'!C9 -> ABCTRANS | E9: ='Panel Data (Long Format)'!D9 -> ABC Transport Plc | F9: ='Panel Data (Long Format)'!E9 -> SERVICES | G9: ='Panel Data (Long Format)'!F9 -> 2023 | H9: 0 | I9: 0 | J9: 0 | K9: 0 | L9: 0 | M9: 0 | N9: 0 | O9: 0 | P9: 0 | Q9: 0 | R9: 0 | S9: 0 | T9: 0 | U9: 0 | V9: 0 | W9: 1 | X9: 0 | Y9: 0 | Z9: 0 | AA9: 0 | AB9: =IF(COUNTBLANK(H9:AA9)>0,"",SUM(H9:AA9)) -> 1 | AC9: =IF(AB9="","",AB9/20*100) -> 5 | AD9: 0 | AE9: 0 | AF9: 0 | AG9: 0 | AH9: 0 | AI9: 0 | AJ9: 0 | AK9: 0 | AL9: 0 | AM9: 0 | AN9: 0 | AO9: 0 | AP9: 0 | AQ9: 0 | AR9: 0 | AS9: =IF(COUNTBLANK(AD9:AR9)>0,"",SUM(AD9:AR9)) -> 0 | AT9: =IF(AS9="","",AS9/15*100) -> 0 | AU9: GAP-FILL: ABCTRANS FY2023: SDQ_M1=1 - a GENUINE confirmed comparative figure was located within the FY2024 Annual Report and Consolidated and Separate Financial Statements (NGX doclib, fetched directly), Note 8 'DONATIONS AND GIFTS', showing a two-column table (headers both mislabelled '2024' in the source PDF, but representing FY2024 and its FY2023 comparative per standard AFS format) with a comparative total of N2,326,000 for FY2023 (vs N4,234,000 for FY2024, which was already coded in an earlier batch). No sustainability-specific board committee or climate content found in this document. CDQ=0/15.
A10: =C10&"_"&G10 -> 2_2024 | B10: 9 | C10: ='Panel Data (Long Format)'!B10 -> 2 | D10: ='Panel Data (Long Format)'!C10 -> ABCTRANS | E10: ='Panel Data (Long Format)'!D10 -> ABC Transport Plc | F10: ='Panel Data (Long Format)'!E10 -> SERVICES | G10: ='Panel Data (Long Format)'!F10 -> 2024 | H10: 0 | I10: 0 | J10: 0 | K10: 0 | L10: 0 | M10: 0 | N10: 0 | O10: 0 | P10: 0 | Q10: 0 | R10: 0 | S10: 0 | T10: 0 | U10: 0 | V10: 0 | W10: 0 | X10: 0 | Y10: 0 | Z10: 0 | AA10: 0 | AB10: =IF(COUNTBLANK(H10:AA10)>0,"",SUM(H10:AA10)) -> 0 | AC10: =IF(AB10="","",AB10/20*100) -> 0 | AD10: 0 | AE10: 0 | AF10: 0 | AG10: 0 | AH10: 0 | AI10: 0 | AJ10: 0 | AK10: 0 | AL10: 0 | AM10: 0 | AN10: 0 | AO10: 0 | AP10: 0 | AQ10: 0 | AR10: 0 | AS10: =IF(COUNTBLANK(AD10:AR10)>0,"",SUM(AD10:AR10)) -> 0 | AT10: =IF(AS10="","",AS10/15*100) -> 0 | AU10: ABC Transport Plc, Annual Report and Consolidated and Separate Financial Statements FYE 31-Dec-2024 (Corporate Information p.1, Notes to the Financial Statements -- Adoption of new and revised standards). Source: doclib.ngxgroup.com (43623_ABC_TRANSPORT_PLC..._2024...pdf), full text extracted and read. Board composition identical to FY2025: Chairman + Managing Director + 1 Executive Director + 4 Non-Executive Directors + 1 Independent Non-Executive Director = 8 total -> Board_Independence=12.5%. IFRS_S1S2_Adopter_Dummy=0, EXPLICITLY EVIDENCED: identical 'not yet adopted' note as FY2025 -- 'The mandatory adoption date is 1 January 2028... effective for annual reporting periods beginning on or after 1 January 2028, with earlier application permitted', explicitly listed among standards 'not yet effective as at 31 December 2024 and have not been early adopted by the Company'. All SDQ/CDQ items score 0: same thin-disclosure pattern as FY2022/FY2025 -- 'accident rate...well within acceptable limits' with no specific figure, no sustainability-specific governance/risk/target content, no substantial-interest-in-shares table found. SDQ=0/20=0%, CDQ=0/15=0%.
A11: =C11&"_"&G11 -> 2_2025 | B11: 10 | C11: ='Panel Data (Long Format)'!B11 -> 2 | D11: ='Panel Data (Long Format)'!C11 -> ABCTRANS | E11: ='Panel Data (Long Format)'!D11 -> ABC Transport Plc | F11: ='Panel Data (Long Format)'!E11 -> SERVICES | G11: ='Panel Data (Long Format)'!F11 -> 2025 | H11: 0 | I11: 0 | J11: 0 | K11: 0 | L11: 0 | M11: 0 | N11: 0 | O11: 0 | P11: 0 | Q11: 0 | R11: 0 | S11: 0 | T11: 0 | U11: 0 | V11: 0 | W11: 0 | X11: 0 | Y11: 0 | Z11: 0 | AA11: 0 | AB11: =IF(COUNTBLANK(H11:AA11)>0,"",SUM(H11:AA11)) -> 0 | AC11: =IF(AB11="","",AB11/20*100) -> 0 | AD11: 0 | AE11: 0 | AF11: 0 | AG11: 0 | AH11: 0 | AI11: 0 | AJ11: 0 | AK11: 0 | AL11: 0 | AM11: 0 | AN11: 0 | AO11: 0 | AP11: 0 | AQ11: 0 | AR11: 0 | AS11: =IF(COUNTBLANK(AD11:AR11)>0,"",SUM(AD11:AR11)) -> 0 | AT11: =IF(AS11="","",AS11/15*100) -> 0 | AU11: ABC Transport Plc, Consolidated and Separate Annual Report and Financial Statements FYE 31-Dec-2025 (Corporate Information p.1, Report of the Directors, Notes to the Financial Statements -- Adoption of new and revised standards). Source: doclib.ngxgroup.com (46506_ABC_TRANSPORT_PLC..._2025...pdf), full text extracted and read. Board composition explicitly stated (Corporate Information page): Chairman + Managing Director + 1 Executive Director + 4 Non-Executive Directors + 1 Independent Non-Executive Director = 8 total -> Board_Independence=12.5%. IFRS_S1S2_Adopter_Dummy=0, EXPLICITLY EVIDENCED: Note 2.7/3 'New standards, amendments and interpretations not yet adopted' lists 'IFRS S1 General Requirements for Disclosure of Sustainability-related Financial Information' with 'The mandatory adoption date is 1 January 2028... effective for annual reporting periods beginning on or after 1 January 2028, with earlier application permitted' -- boilerplate acknowledging the future standard exists, with no indication the company chose early/voluntary application, so this is a confirmed NON-adopter, not a blank/unknown. This same note structure also means the standard's four-pillar description in the note itself is NOT scored toward SDQ/CDQ (it describes what the future standard will require, not the entity's own current disclosure practice). All SDQ/CDQ items score 0: same thin-disclosure pattern as FY2022 -- safety/accident -rate language present but no specific figure, no sustainability-specific governance/risk/target content. No 'substantial interest in shares' table found -- Ownership_Concentration left blank (optional field). SDQ=0/20=0%, CDQ=0/15=0%.
A12: =C12&"_"&G12 -> 3_2021 | B12: 11 | C12: ='Panel Data (Long Format)'!B12 -> 3 | D12: ='Panel Data (Long Format)'!C12 -> ACADEMY | E12: ='Panel Data (Long Format)'!D12 -> Academy Press Plc | F12: ='Panel Data (Long Format)'!E12 -> SERVICES | G12: ='Panel Data (Long Format)'!F12 -> 2021 | H12: 0 | I12: 0 | J12: 0 | K12: 0 | L12: 0 | M12: 0 | N12: 0 | O12: 0 | P12: 0 | Q12: 0 | R12: 0 | S12: 0 | T12: 0 | U12: 0 | V12: 0 | W12: 0 | X12: 0 | Y12: 0 | Z12: 0 | AA12: 0 | AB12: =IF(COUNTBLANK(H12:AA12)>0,"",SUM(H12:AA12)) -> 0 | AC12: =IF(AB12="","",AB12/20*100) -> 0 | AD12: 0 | AE12: 0 | AF12: 0 | AG12: 0 | AH12: 0 | AI12: 0 | AJ12: 0 | AK12: 0 | AL12: 0 | AM12: 0 | AN12: 0 | AO12: 0 | AP12: 0 | AQ12: 0 | AR12: 0 | AS12: =IF(COUNTBLANK(AD12:AR12)>0,"",SUM(AD12:AR12)) -> 0 | AT12: =IF(AS12="","",AS12/15*100) -> 0 | AU12: GAP-FILL: ACADEMY FY2021: not verified this session - the only primary source successfully fetched was the Annual Report for the year ended 31 March 2024 (NGX doclib), whose comparative column covers FY2023 only. Scored 0/20 SDQ, 0/15 CDQ, FLAGGED as unconfirmed pending re-verification against a dedicated FY2021 filing.
A13: =C13&"_"&G13 -> 3_2022 | B13: 12 | C13: ='Panel Data (Long Format)'!B13 -> 3 | D13: ='Panel Data (Long Format)'!C13 -> ACADEMY | E13: ='Panel Data (Long Format)'!D13 -> Academy Press Plc | F13: ='Panel Data (Long Format)'!E13 -> SERVICES | G13: ='Panel Data (Long Format)'!F13 -> 2022 | H13: 0 | I13: 0 | J13: 0 | K13: 0 | L13: 0 | M13: 0 | N13: 0 | O13: 0 | P13: 0 | Q13: 0 | R13: 0 | S13: 0 | T13: 0 | U13: 0 | V13: 0 | W13: 0 | X13: 0 | Y13: 0 | Z13: 0 | AA13: 0 | AB13: =IF(COUNTBLANK(H13:AA13)>0,"",SUM(H13:AA13)) -> 0 | AC13: =IF(AB13="","",AB13/20*100) -> 0 | AD13: 0 | AE13: 0 | AF13: 0 | AG13: 0 | AH13: 0 | AI13: 0 | AJ13: 0 | AK13: 0 | AL13: 0 | AM13: 0 | AN13: 0 | AO13: 0 | AP13: 0 | AQ13: 0 | AR13: 0 | AS13: =IF(COUNTBLANK(AD13:AR13)>0,"",SUM(AD13:AR13)) -> 0 | AT13: =IF(AS13="","",AS13/15*100) -> 0 | AU13: GAP-FILL: ACADEMY FY2022: not verified this session - the only primary source successfully fetched was the Annual Report for the year ended 31 March 2024 (NGX doclib), whose comparative column covers FY2023 only. Scored 0/20 SDQ, 0/15 CDQ, FLAGGED as unconfirmed pending re-verification against a dedicated FY2022 filing.
... A23: =C23&"_"&G23 -> 5_2022 | B23: 22 | C23: ='Panel Data (Long Format)'!B23 -> 5 | D23: ='Panel Data (Long Format)'!C23 -> AFRINSURE | E23: ='Panel Data (Long Format)'!D23 -> African Alliance Insurance Plc | F23: ='Panel Data (Long Format)'!E23 -> FINANCIAL SERVICES | G23: ='Panel Data (Long Format)'!F23 -> 2022 | H23: 0 | I23: 0 | J23: 0 | K23: 0 | L23: 0 | M23: 0 | N23: 0 | O23: 0 | P23: 0 | Q23: 0 | R23: 0 | S23: 0 | T23: 0 | U23: 0 | V23: 0 | W23: 0 | X23: 0 | Y23: 0 | Z23: 0 | AA23: 0 | AB23: =IF(COUNTBLANK(H23:AA23)>0,"",SUM(H23:AA23)) -> 0 | AC23: =IF(AB23="","",AB23/20*100) -> 0 | AD23: 0 | AE23: 0 | AF23: 0 | AG23: 0 | AH23: 0 | AI23: 0 | AJ23: 0 | AK23: 0 | AL23: 0 | AM23: 0 | AN23: 0 | AO23: 0 | AP23: 0 | AQ23: 0 | AR23: 0 | AS23: =IF(COUNTBLANK(AD23:AR23)>0,"",SUM(AD23:AR23)) -> 0 | AT23: =IF(AS23="","",AS23/15*100) -> 0 | AU23: African Alliance Insurance Plc FY2022 Consolidated FS (NGX doclib #39898, filed Nov-2023, late-filed). Zero sustainability/climate/ESG keyword occurrences confirmed by full-document search.
A24: =C24&"_"&G24 -> 5_2023 | B24: 23 | C24: ='Panel Data (Long Format)'!B24 -> 5 | D24: ='Panel Data (Long Format)'!C24 -> AFRINSURE | E24: ='Panel Data (Long Format)'!D24 -> African Alliance Insurance Plc | F24: ='Panel Data (Long Format)'!E24 -> FINANCIAL SERVICES | G24: ='Panel Data (Long Format)'!F24 -> 2023 | AB24: =IF(COUNTBLANK(H24:AA24)>0,"",SUM(H24:AA24)) | AC24: =IF(AB24="","",AB24/20*100) | AS24: =IF(COUNTBLANK(AD24:AR24)>0,"",SUM(AD24:AR24)) | AT24: =IF(AS24="","",AS24/15*100) | AU24: GENUINE GAP: NGX suspended AFRINSURE trading for late/non-filing; NAICOM dissolved the company's board and management in October 2024 over solvency concerns; NAICOM only handed control to a new board in June 2026. Web/doclib searches found no FY2023 audited FS filed.
A25: =C25&"_"&G25 -> 5_2024 | B25: 24 | C25: ='Panel Data (Long Format)'!B25 -> 5 | D25: ='Panel Data (Long Format)'!C25 -> AFRINSURE | E25: ='Panel Data (Long Format)'!D25 -> African Alliance Insurance Plc | F25: ='Panel Data (Long Format)'!E25 -> FINANCIAL SERVICES | G25: ='Panel Data (Long Format)'!F25 -> 2024 | AB25: =IF(COUNTBLANK(H25:AA25)>0,"",SUM(H25:AA25)) | AC25: =IF(AB25="","",AB25/20*100) | AS25: =IF(COUNTBLANK(AD25:AR25)>0,"",SUM(AD25:AR25)) | AT25: =IF(AS25="","",AS25/15*100) | AU25: GENUINE GAP: Same regulatory breakdown as FY2023 (board dissolved Oct-2024 mid-year); no FY2024 audited FS located despite search attempts.
A26: =C26&"_"&G26 -> 5_2025 | B26: 25 | C26: ='Panel Data (Long Format)'!B26 -> 5 | D26: ='Panel Data (Long Format)'!C26 -> AFRINSURE | E26: ='Panel Data (Long Format)'!D26 -> African Alliance Insurance Plc | F26: ='Panel Data (Long Format)'!E26 -> FINANCIAL SERVICES | G26: ='Panel Data (Long Format)'!F26 -> 2025 | AB26: =IF(COUNTBLANK(H26:AA26)>0,"",SUM(H26:AA26)) | AC26: =IF(AB26="","",AB26/20*100) | AS26: =IF(COUNTBLANK(AD26:AR26)>0,"",SUM(AD26:AR26)) | AT26: =IF(AS26="","",AS26/15*100) | AU26: GENUINE GAP: Company under NAICOM-appointed interim management through most of FY2025; new board only installed June 2026; no FY2025 audited FS located.
A27: =C27&"_"&G27 -> 6_2021 | B27: 26 | C27: ='Panel Data (Long Format)'!B27 -> 6 | D27: ='Panel Data (Long Format)'!C27 -> AFRIPRUD | E27: ='Panel Data (Long Format)'!D27 -> Africa Prudential Plc | F27: ='Panel Data (Long Format)'!E27 -> FINANCIAL SERVICES | G27: ='Panel Data (Long Format)'!F27 -> 2021 | H27: 0 | I27: 0 | J27: 0 | K27: 0 | L27: 0 | M27: 0 | N27: 0 | O27: 0 | P27: 0 | Q27: 0 | R27: 0 | S27: 0 | T27: 0 | U27: 0 | V27: 0 | W27: 0 | X27: 0 | Y27: 0 | Z27: 0 | AA27: 0 | AB27: =IF(COUNTBLANK(H27:AA27)>0,"",SUM(H27:AA27)) -> 0 | AC27: =IF(AB27="","",AB27/20*100) -> 0 | AD27: 0 | AE27: 0 | AF27: 0 | AG27: 0 | AH27: 0 | AI27: 0 | AJ27: 0 | AK27: 0 | AL27: 0 | AM27: 0 | AN27: 0 | AO27: 0 | AP27: 0 | AQ27: 0 | AR27: 0 | AS27: =IF(COUNTBLANK(AD27:AR27)>0,"",SUM(AD27:AR27)) -> 0 | AT27: =IF(AS27="","",AS27/15*100) -> 0 | AU27: Africa Prudential Plc FY2021 Audited FS (NGX doclib #35166), 'Sustainability and CSR Report' section. No board-level sustainability committee (only Audit&Governance, Finance&Investment, Product&Projects committees exist). Generic CSR narrative only (tree planting, energy-efficient bulbs, EDMMS portal reducing 'fuel use/CO2'); explicitly states 'implementation of Sustainability Principles will continue to remain a work in progress.' No metrics, targets, or specific risks named.
A28: =C28&"_"&G28 -> 6_2022 | B28: 27 | C28: ='Panel Data (Long Format)'!B28 -> 6 | D28: ='Panel Data (Long Format)'!C28 -> AFRIPRUD | E28: ='Panel Data (Long Format)'!D28 -> Africa Prudential Plc | F28: ='Panel Data (Long Format)'!E28 -> FINANCIAL SERVICES | G28: ='Panel Data (Long Format)'!F28 -> 2022 | H28: 0 | I28: 0 | J28: 0 | K28: 0 | L28: 0 | M28: 0 | N28: 0 | O28: 0 | P28: 0 | Q28: 0 | R28: 0 | S28: 0 | T28: 0 | U28: 0 | V28: 0 | W28: 0 | X28: 0 | Y28: 0 | Z28: 0 | AA28: 0 | AB28: =IF(COUNTBLANK(H28:AA28)>0,"",SUM(H28:AA28)) -> 0 | AC28: =IF(AB28="","",AB28/20*100) -> 0 | AD28: 0 | AE28: 0 | AF28: 0 | AG28: 0 | AH28: 0 | AI28: 0 | AJ28: 0 | AK28: 0 | AL28: 0 | AM28: 0 | AN28: 0 | AO28: 0 | AP28: 0 | AQ28: 0 | AR28: 0 | AS28: =IF(COUNTBLANK(AD28:AR28)>0,"",SUM(AD28:AR28)) -> 0 | AT28: =IF(AS28="","",AS28/15*100) -> 0 | AU28: Africa Prudential Plc FY2022 Audited FS (NGX doclib, Africa_Prudential_Plc_-_2022_AFS.pdf). Same boilerplate CR&S pattern as FY2021/2023/2024, confirmed by cross-year text comparison.
A29: =C29&"_"&G29 -> 6_2023 | B29: 28 | C29: ='Panel Data (Long Format)'!B29 -> 6 | D29: ='Panel Data (Long Format)'!C29 -> AFRIPRUD | E29: ='Panel Data (Long Format)'!D29 -> Africa Prudential Plc | F29: ='Panel Data (Long Format)'!E29 -> FINANCIAL SERVICES | G29: ='Panel Data (Long Format)'!F29 -> 2023 | H29: 0 | I29: 0 | J29: 0 | K29: 0 | L29: 0 | M29: 0 | N29: 0 | O29: 0 | P29: 0 | Q29: 0 | R29: 0 | S29: 0 | T29: 0 | U29: 0 | V29: 0 | W29: 0 | X29: 0 | Y29: 0 | Z29: 0 | AA29: 0 | AB29: =IF(COUNTBLANK(H29:AA29)>0,"",SUM(H29:AA29)) -> 0 | AC29: =IF(AB29="","",AB29/20*100) -> 0 | AD29: 0 | AE29: 0 | AF29: 0 | AG29: 0 | AH29: 0 | AI29: 0 | AJ29: 0 | AK29: 0 | AL29: 0 | AM29: 0 | AN29: 0 | AO29: 0 | AP29: 0 | AQ29: 0 | AR29: 0 | AS29: =IF(COUNTBLANK(AD29:AR29)>0,"",SUM(AD29:AR29)) -> 0 | AT29: =IF(AS29="","",AS29/15*100) -> 0 | AU29: Africa Prudential Plc FY2023 Audited FS (NGX doclib #40447). CSR/Sustainability text verbatim-identical to FY2021 report. No IFRS S1/S2/ISSB mention despite FRC Nigeria externally listing AFRIPRUD as a 'voluntary adopter' -- nothing in this document itself supports that as of FY2023; coded strictly from primary-document text per project convention.
A30: =C30&"_"&G30 -> 6_2024 | B30: 29 | C30: ='Panel Data (Long Format)'!B30 -> 6 | D30: ='Panel Data (Long Format)'!C30 -> AFRIPRUD | E30: ='Panel Data (Long Format)'!D30 -> Africa Prudential Plc | F30: ='Panel Data (Long Format)'!E30 -> FINANCIAL SERVICES | G30: ='Panel Data (Long Format)'!F30 -> 2024 | H30: 0 | I30: 0 | J30: 0 | K30: 0 | L30: 0 | M30: 0 | N30: 0 | O30: 0 | P30: 0 | Q30: 0 | R30: 0 | S30: 0 | T30: 0 | U30: 0 | V30: 0 | W30: 0 | X30: 0 | Y30: 0 | Z30: 0 | AA30: 0 | AB30: =IF(COUNTBLANK(H30:AA30)>0,"",SUM(H30:AA30)) -> 0 | AC30: =IF(AB30="","",AB30/20*100) -> 0 | AD30: 0 | AE30: 0 | AF30: 0 | AG30: 0 | AH30: 0 | AI30: 0 | AJ30: 0 | AK30: 0 | AL30: 0 | AM30: 0 | AN30: 0 | AO30: 0 | AP30: 0 | AQ30: 0 | AR30: 0 | AS30: =IF(COUNTBLANK(AD30:AR30)>0,"",SUM(AD30:AR30)) -> 0 | AT30: =IF(AS30="","",AS30/15*100) -> 0 | AU30: Africa Prudential Plc FY2024 Audited FS (NGX doclib #43304). CSR/Sustainability section again verbatim-identical to prior years. No board sustainability oversight, no metrics, no IFRS S1/S2 mention found.
A31: =C31&"_"&G31 -> 6_2025 | B31: 30 | C31: ='Panel Data (Long Format)'!B31 -> 6 | D31: ='Panel Data (Long Format)'!C31 -> AFRIPRUD | E31: ='Panel Data (Long Format)'!D31 -> Africa Prudential Plc | F31: ='Panel Data (Long Format)'!E31 -> FINANCIAL SERVICES | G31: ='Panel Data (Long Format)'!F31 -> 2025 | H31: 0 | I31: 0 | J31: 0 | K31: 0 | L31: 0 | M31: 0 | N31: 0 | O31: 0 | P31: 0 | Q31: 0 | R31: 0 | S31: 0 | T31: 0 | U31: 0 | V31: 0 | W31: 0 | X31: 0 | Y31: 0 | Z31: 0 | AA31: 0 | AB31: =IF(COUNTBLANK(H31:AA31)>0,"",SUM(H31:AA31)) -> 0 | AC31: =IF(AB31="","",AB31/20*100) -> 0 | AD31: 0 | AE31: 0 | AF31: 0 | AG31: 0 | AH31: 0 | AI31: 0 | AJ31: 0 | AK31: 0 | AL31: 0 | AM31: 0 | AN31: 0 | AO31: 0 | AP31: 0 | AQ31: 0 | AR31: 0 | AS31: =IF(COUNTBLANK(AD31:AR31)>0,"",SUM(AD31:AR31)) -> 0 | AT31: =IF(AS31="","",AS31/15*100) -> 0 | AU31: Africa Prudential Plc FY2025 Audited FS (NGX doclib, AFRICA_PRUDENTIAL_PLC_-_2025_AUDITED_FINANCIAL_STATEMENTS.pdf). Sustainability section rewritten with more modern language ('Our Sustainability Philosophy', 'ESG approach', reduced travel emissions) but still no quantified metrics, no targets, no board committee, and critically no IFRS S1/S2/ISSB mention despite FRC's external 'voluntary adopter' designation -- coded strictly from document text per project convention.
A32: =C32&"_"&G32 -> 7_2021 | B32: 31 | C32: ='Panel Data (Long Format)'!B32 -> 7 | D32: ='Panel Data (Long Format)'!C32 -> AFROMEDIA | E32: ='Panel Data (Long Format)'!D32 -> Afromedia Plc | F32: ='Panel Data (Long Format)'!E32 -> SERVICES | G32: ='Panel Data (Long Format)'!F32 -> 2021 | H32: 0 | I32: 0 | J32: 0 | K32: 0 | L32: 0 | M32: 0 | N32: 0 | O32: 0 | P32: 0 | Q32: 0 | R32: 0 | S32: 0 | T32: 0 | U32: 0 | V32: 0 | W32: 0 | X32: 0 | Y32: 0 | Z32: 0 | AA32: 0 | AB32: =IF(COUNTBLANK(H32:AA32)>0,"",SUM(H32:AA32)) -> 0 | AC32: =IF(AB32="","",AB32/20*100) -> 0 | AD32: 0 | AE32: 0 | AF32: 0 | AG32: 0 | AH32: 0 | AI32: 0 | AJ32: 0 | AK32: 0 | AL32: 0 | AM32: 0 | AN32: 0 | AO32: 0 | AP32: 0 | AQ32: 0 | AR32: 0 | AS32: =IF(COUNTBLANK(AD32:AR32)>0,"",SUM(AD32:AR32)) -> 0 | AT32: =IF(AS32="","",AS32/15*100) -> 0 | AU32: Afromedia Plc FY2021 Audited FS (NGX doclib #35538). Zero sustainability/climate/ESG/GHG/carbon keyword occurrences. Only generic 'committee' references are audit committee and IFRS-8 steering committee (segment reporting), not sustainability-related.
A33: =C33&"_"&G33 -> 7_2022 | B33: 32 | C33: ='Panel Data (Long Format)'!B33 -> 7 | D33: ='Panel Data (Long Format)'!C33 -> AFROMEDIA | E33: ='Panel Data (Long Format)'!D33 -> Afromedia Plc | F33: ='Panel Data (Long Format)'!E33 -> SERVICES | G33: ='Panel Data (Long Format)'!F33 -> 2022 | H33: 0 | I33: 0 | J33: 0 | K33: 0 | L33: 0 | M33: 0 | N33: 0 | O33: 0 | P33: 0 | Q33: 0 | R33: 0 | S33: 0 | T33: 0 | U33: 0 | V33: 0 | W33: 0 | X33: 0 | Y33: 0 | Z33: 0 | AA33: 0 | AB33: =IF(COUNTBLANK(H33:AA33)>0,"",SUM(H33:AA33)) -> 0 | AC33: =IF(AB33="","",AB33/20*100) -> 0 | AD33: 0 | AE33: 0 | AF33: 0 | AG33: 0 | AH33: 0 | AI33: 0 | AJ33: 0 | AK33: 0 | AL33: 0 | AM33: 0 | AN33: 0 | AO33: 0 | AP33: 0 | AQ33: 0 | AR33: 0 | AS33: =IF(COUNTBLANK(AD33:AR33)>0,"",SUM(AD33:AR33)) -> 0 | AT33: =IF(AS33="","",AS33/15*100) -> 0 | AU33: Afromedia Plc FY2022 Audited FS (NGX doclib #39227, filed Aug-2023). Zero sustainability/climate/ESG keyword occurrences. Filing found despite prior-sweep 'NOT_FOUND' flag -- filed late, shortly after NGX suspended the stock (11-Jul-2023) for non-filing.
A34: =C34&"_"&G34 -> 7_2023 | B34: 33 | C34: ='Panel Data (Long Format)'!B34 -> 7 | D34: ='Panel Data (Long Format)'!C34 -> AFROMEDIA | E34: ='Panel Data (Long Format)'!D34 -> Afromedia Plc | F34: ='Panel Data (Long Format)'!E34 -> SERVICES | G34: ='Panel Data (Long Format)'!F34 -> 2023 | AB34: =IF(COUNTBLANK(H34:AA34)>0,"",SUM(H34:AA34)) | AC34: =IF(AB34="","",AB34/20*100) | AS34: =IF(COUNTBLANK(AD34:AR34)>0,"",SUM(AD34:AR34)) | AT34: =IF(AS34="","",AS34/15*100) | AU34: GENUINE GAP: AFROMEDIA suspended from NGX trading facilities effective 11-Jul-2023 for failing to file FY2022 accounts on time; no FY2023 audited FS located. Company reported to be under going-concern uncertainty.
A35: =C35&"_"&G35 -> 7_2024 | B35: 34 | C35: ='Panel Data (Long Format)'!B35 -> 7 | D35: ='Panel Data (Long Format)'!C35 -> AFROMEDIA | E35: ='Panel Data (Long Format)'!D35 -> Afromedia Plc | F35: ='Panel Data (Long Format)'!E35 -> SERVICES | G35: ='Panel Data (Long Format)'!F35 -> 2024 | AB35: =IF(COUNTBLANK(H35:AA35)>0,"",SUM(H35:AA35)) | AC35: =IF(AB35="","",AB35/20*100) | AS35: =IF(COUNTBLANK(AD35:AR35)>0,"",SUM(AD35:AR35)) | AT35: =IF(AS35="","",AS35/15*100) | AU35: GENUINE GAP: No FY2024 audited FS located; company remains suspended/delinquent on NGX.
A36: =C36&"_"&G36 -> 7_2025 | B36: 35 | C36: ='Panel Data (Long Format)'!B36 -> 7 | D36: ='Panel Data (Long Format)'!C36 -> AFROMEDIA | E36: ='Panel Data (Long Format)'!D36 -> Afromedia Plc | F36: ='Panel Data (Long Format)'!E36 -> SERVICES | G36: ='Panel Data (Long Format)'!F36 -> 2025 | AB36: =IF(COUNTBLANK(H36:AA36)>0,"",SUM(H36:AA36)) | AC36: =IF(AB36="","",AB36/20*100) | AS36: =IF(COUNTBLANK(AD36:AR36)>0,"",SUM(AD36:AR36)) | AT36: =IF(AS36="","",AS36/15*100) | AU36: GENUINE GAP: No FY2025 audited FS located; no evidence of resumed filing found.
A37: =C37&"_"&G37 -> 8_2021 | B37: 36 | C37: ='Panel Data (Long Format)'!B37 -> 8 | D37: ='Panel Data (Long Format)'!C37 -> AIICO | E37: ='Panel Data (Long Format)'!D37 -> AIICO Insurance Plc | F37: ='Panel Data (Long Format)'!E37 -> FINANCIAL SERVICES | G37: ='Panel Data (Long Format)'!F37 -> 2021 | H37: 1 | I37: 1 | J37: 0 | K37: 0 | L37: 0 | M37: 0 | N37: 0 | O37: 0 | P37: 0 | Q37: 0 | R37: 1 | S37: 0 | T37: 1 | U37: 1 | V37: 0 | W37: 0 | X37: 0 | Y37: 0 | Z37: 0 | AA37: 0 | AB37: =IF(COUNTBLANK(H37:AA37)>0,"",SUM(H37:AA37)) -> 5 | AC37: =IF(AB37="","",AB37/20*100) -> 25 | AD37: 0 | AE37: 0 | AF37: 0 | AG37: 0 | AH37: 0 | AI37: 0 | AJ37: 0 | AK37: 0 | AL37: 0 | AM37: 0 | AN37: 0 | AO37: 0 | AP37: 0 | AQ37: 0 | AR37: 0 | AS37: =IF(COUNTBLANK(AD37:AR37)>0,"",SUM(AD37:AR37)) -> 0 | AT37: =IF(AS37="","",AS37/15*100) -> 0 | AU37: AIICO Insurance Plc 2021 Annual Report (aiicoplc.com). Generic 'Corporate Responsibility & Sustainability Policy' narrative; CR&S Unit + Environmental and Social Committee (reports to Board/Exec Mgmt) named (G1,G2=1). SEMS (Social & Environmental Mgmt Systems, est. 2016) cited as 'integral part of risk assessment process' (R1,R4=1). No frequency/mechanism detail, no quantified metrics/targets, no climate-specific content anywhere.
A38: =C38&"_"&G38 -> 8_2022 | B38: 37 | C38: ='Panel Data (Long Format)'!B38 -> 8 | D38: ='Panel Data (Long Format)'!C38 -> AIICO | E38: ='Panel Data (Long Format)'!D38 -> AIICO Insurance Plc | F38: ='Panel Data (Long Format)'!E38 -> FINANCIAL SERVICES | G38: ='Panel Data (Long Format)'!F38 -> 2022 | H38: 1 | I38: 1 | J38: 0 | K38: 0 | L38: 0 | M38: 0 | N38: 0 | O38: 0 | P38: 0 | Q38: 0 | R38: 1 | S38: 0 | T38: 1 | U38: 1 | V38: 0 | W38: 0 | X38: 0 | Y38: 0 | Z38: 0 | AA38: 0 | AB38: =IF(COUNTBLANK(H38:AA38)>0,"",SUM(H38:AA38)) -> 5 | AC38: =IF(AB38="","",AB38/20*100) -> 25 | AD38: 0 | AE38: 0 | AF38: 0 | AG38: 0 | AH38: 0 | AI38: 0 | AJ38: 0 | AK38: 0 | AL38: 0 | AM38: 0 | AN38: 0 | AO38: 0 | AP38: 0 | AQ38: 0 | AR38: 0 | AS38: =IF(COUNTBLANK(AD38:AR38)>0,"",SUM(AD38:AR38)) -> 0 | AT38: =IF(AS38="","",AS38/15*100) -> 0 | AU38: AIICO Insurance Plc 2022 Annual Report (aiicoplc.com). CR&S policy text verbatim-identical to FY2021 report (confirmed by direct text comparison) -- same coding applies.
A39: =C39&"_"&G39 -> 8_2023 | B39: 38 | C39: ='Panel Data (Long Format)'!B39 -> 8 | D39: ='Panel Data (Long Format)'!C39 -> AIICO | E39: ='Panel Data (Long Format)'!D39 -> AIICO Insurance Plc | F39: ='Panel Data (Long Format)'!E39 -> FINANCIAL SERVICES | G39: ='Panel Data (Long Format)'!F39 -> 2023 | H39: 1 | I39: 1 | J39: 0 | K39: 0 | L39: 0 | M39: 0 | N39: 0 | O39: 0 | P39: 0 | Q39: 0 | R39: 1 | S39: 0 | T39: 1 | U39: 1 | V39: 0 | W39: 0 | X39: 0 | Y39: 0 | Z39: 0 | AA39: 0 | AB39: =IF(COUNTBLANK(H39:AA39)>0,"",SUM(H39:AA39)) -> 5 | AC39: =IF(AB39="","",AB39/20*100) -> 25 | AD39: 0 | AE39: 0 | AF39: 0 | AG39: 0 | AH39: 0 | AI39: 0 | AJ39: 0 | AK39: 0 | AL39: 0 | AM39: 0 | AN39: 0 | AO39: 0 | AP39: 0 | AQ39: 0 | AR39: 0 | AS39: =IF(COUNTBLANK(AD39:AR39)>0,"",SUM(AD39:AR39)) -> 0 | AT39: =IF(AS39="","",AS39/15*100) -> 0 | AU39: AIICO Insurance Plc 2023 Annual Report (aiicoplc.com). CR&S policy text again verbatim-identical to FY2021/FY2022. No IFRS S1/S2/ISSB mention anywhere.
A40: =C40&"_"&G40 -> 8_2024 | B40: 39 | C40: ='Panel Data (Long Format)'!B40 -> 8 | D40: ='Panel Data (Long Format)'!C40 -> AIICO | E40: ='Panel Data (Long Format)'!D40 -> AIICO Insurance Plc | F40: ='Panel Data (Long Format)'!E40 -> FINANCIAL SERVICES | G40: ='Panel Data (Long Format)'!F40 -> 2024 | H40: 1 | I40: 1 | J40: 0 | K40: 0 | L40: 0 | M40: 0 | N40: 0 | O40: 0 | P40: 0 | Q40: 0 | R40: 1 | S40: 0 | T40: 1 | U40: 1 | V40: 0 | W40: 0 | X40: 0 | Y40: 0 | Z40: 0 | AA40: 0 | AB40: =IF(COUNTBLANK(H40:AA40)>0,"",SUM(H40:AA40)) -> 5 | AC40: =IF(AB40="","",AB40/20*100) -> 25 | AD40: 0 | AE40: 0 | AF40: 0 | AG40: 0 | AH40: 0 | AI40: 0 | AJ40: 0 | AK40: 0 | AL40: 0 | AM40: 0 | AN40: 0 | AO40: 0 | AP40: 0 | AQ40: 0 | AR40: 0 | AS40: =IF(COUNTBLANK(AD40:AR40)>0,"",SUM(AD40:AR40)) -> 0 | AT40: =IF(AS40="","",AS40/15*100) -> 0 | AU40: AIICO Insurance Plc 2024 Annual Report (aiicoplc.com). Boilerplate CR&S text confirmed unchanged from prior years. No metrics, no IFRS S1/S2 mention.
A41: =C41&"_"&G41 -> 8_2025 | B41: 40 | C41: ='Panel Data (Long Format)'!B41 -> 8 | D41: ='Panel Data (Long Format)'!C41 -> AIICO | E41: ='Panel Data (Long Format)'!D41 -> AIICO Insurance Plc | F41: ='Panel Data (Long Format)'!E41 -> FINANCIAL SERVICES | G41: ='Panel Data (Long Format)'!F41 -> 2025 | H41: 1 | I41: 1 | J41: 0 | K41: 0 | L41: 0 | M41: 1 | N41: 1 | O41: 1 | P41: 0 | Q41: 0 | R41: 1 | S41: 0 | T41: 1 | U41: 1 | V41: 0 | W41: 1 | X41: 0 | Y41: 0 | Z41: 0 | AA41: 1 | AB41: =IF(COUNTBLANK(H41:AA41)>0,"",SUM(H41:AA41)) -> 10 | AC41: =IF(AB41="","",AB41/20*100) -> 50 | AD41: 0 | AE41: 0 | AF41: 0 | AG41: 0 | AH41: 1 | AI41: 0 | AJ41: 0 | AK41: 0 | AL41: 0 | AM41: 0 | AN41: 0 | AO41: 0 | AP41: 0 | AQ41: 0 | AR41: 0 | AS41: =IF(COUNTBLANK(AD41:AR41)>0,"",SUM(AD41:AR41)) -> 1 | AT41: =IF(AS41="","",AS41/15*100) -> 6.6666667 | AU41: AIICO Insurance Plc 2025 Annual Report and Accounts (aiicoplc.com). First year with upgraded content: climate-specific insurance products (Weather Index / Area Yield Index for farmers) -> S1/S2/S3=1; GHG emissions tracking methodology named (GHG Protocol referenced but no Scope 1/2/3 figures disclosed -> CDQ M1-3=0); one quantified metric (1,079kg recyclable waste retrieved) -> M1=1; 50 trees donated. Still no IFRS S1/S2 mention, no board sustainability committee detail, no targets-with-progress pairing.
A42: =C42&"_"&G42 -> 9_2021 | B42: 41 | C42: ='Panel Data (Long Format)'!B42 -> 9 | D42: ='Panel Data (Long Format)'!C42 -> AIRTELAFRI | E42: ='Panel Data (Long Format)'!D42 -> Airtel Africa Plc | F42: ='Panel Data (Long Format)'!E42 -> ICT | G42: ='Panel Data (Long Format)'!F42 -> 2021 | H42: 1 | I42: 0 | J42: 0 | K42: 0 | L42: 0 | M42: 0 | N42: 0 | O42: 0 | P42: 0 | Q42: 0 | R42: 0 | S42: 0 | T42: 0 | U42: 0 | V42: 0 | W42: 0 | X42: 0 | Y42: 0 | Z42: 0 | AA42: 0 | AB42: =IF(COUNTBLANK(H42:AA42)>0,"",SUM(H42:AA42)) -> 1 | AC42: =IF(AB42="","",AB42/20*100) -> 5 | AD42: 0 | AE42: 0 | AF42: 0 | AG42: 0 | AH42: 0 | AI42: 0 | AJ42: 0 | AK42: 0 | AL42: 0 | AM42: 0 | AN42: 0 | AO42: 0 | AP42: 0 | AQ42: 0 | AR42: 0 | AS42: =IF(COUNTBLANK(AD42:AR42)>0,"",SUM(AD42:AR42)) -> 0 | AT42: =IF(AS42="","",AS42/15*100) -> 0 | AU42: Airtel Africa Plc FY2021 (FYE 31-Mar-2021) Full Report / Governance Report / Strategic Report (cdn-webportal.airtelstream.net). Governance Report pp.82-99: Board attended a Nov-2020 sustainability workshop and endorsed management's sustainability-reporting approach (G1=1); no dedicated Sustainability Committee yet (only Audit&Risk/Remuneration/Nominations/Market Disclosure committees named); Remuneration Committee's 'embed sustainability into pay' was only a forward-looking 2020/21 recommendation, not yet implemented. Group's sustainability strategy/GHG baseline programme launched Oct-2021, i.e. AFTER this FYE, confirming genuinely near-zero disclosure for this year rather than an extraction gap. No IFRS S1/S2/ISSB language located in fetched 'new standards' sections.
A43: =C43&"_"&G43 -> 9_2022 | B43: 42 | C43: ='Panel Data (Long Format)'!B43 -> 9 | D43: ='Panel Data (Long Format)'!C43 -> AIRTELAFRI | E43: ='Panel Data (Long Format)'!D43 -> Airtel Africa Plc | F43: ='Panel Data (Long Format)'!E43 -> ICT | G43: ='Panel Data (Long Format)'!F43 -> 2022 | H43: 1 | I43: 1 | J43: 1 | K43: 1 | L43: 0 | M43: 1 | N43: 1 | O43: 1 | P43: 0 | Q43: 0 | R43: 1 | S43: 0 | T43: 0 | U43: 0 | V43: 0 | W43: 1 | X43: 1 | Y43: 0 | Z43: 1 | AA43: 1 | AB43: =IF(COUNTBLANK(H43:AA43)>0,"",SUM(H43:AA43)) -> 12 | AC43: =IF(AB43="","",AB43/20*100) -> 60 | AD43: 1 | AE43: 1 | AF43: 0 | AG43: 0 | AH43: 1 | AI43: 0 | AJ43: 1 | AK43: 1 | AL43: 1 | AM43: 1 | AN43: 1 | AO43: 1 | AP43: 0 | AQ43: 0 | AR43: 0 | AS43: =IF(COUNTBLANK(AD43:AR43)>0,"",SUM(AD43:AR43)) -> 9 | AT43: =IF(AS43="","",AS43/15*100) -> 60 | AU43: Airtel Africa Sustainability Report 2022 (cdn-webportal.airtelstream.net), supplemented by FY2021 Governance/Strategic Report continuity. Sustainability Committee (chaired by CEO, meets monthly) formalised as a Board committee alongside Audit&Risk Committee (co-oversees climate risks/opportunities); Board updated quarterly; remuneration policy explicitly integrates sustainability metrics (G4/M4=1). Baseline Scope1+2=115,719 tCO2e, Scope3=534,058 tCO2e reported as of 31-Mar-2022 with stated calculation methodology (M5=1). Net-zero-by-2050 pathway is a forming target, no progress figure yet reportable in baseline year. No scenario analysis or physical/transition risk categorisation found this year. CAVEAT: standalone AR2022 Governance/Strategic Report PDF not independently located this session -- some G/S items may be undercounted, flagged for re-check.
A44: =C44&"_"&G44 -> 9_2023 | B44: 43 | C44: ='Panel Data (Long Format)'!B44 -> 9 | D44: ='Panel Data (Long Format)'!C44 -> AIRTELAFRI | E44: ='Panel Data (Long Format)'!D44 -> Airtel Africa Plc | F44: ='Panel Data (Long Format)'!E44 -> ICT | G44: ='Panel Data (Long Format)'!F44 -> 2023 | H44: 1 | I44: 1 | J44: 1 | K44: 0 | L44: 0 | M44: 1 | N44: 1 | O44: 1 | P44: 0 | Q44: 1 | R44: 1 | S44: 1 | T44: 1 | U44: 1 | V44: 0 | W44: 0 | X44: 0 | Y44: 0 | Z44: 0 | AA44: 0 | AB44: =IF(COUNTBLANK(H44:AA44)>0,"",SUM(H44:AA44)) -> 11 | AC44: =IF(AB44="","",AB44/20*100) -> 55 | AD44: 1 | AE44: 1 | AF44: 0 | AG44: 0 | AH44: 1 | AI44: 1 | AJ44: 1 | AK44: 1 | AL44: 1 | AM44: 0 | AN44: 0 | AO44: 0 | AP44: 1 | AQ44: 0 | AR44: 0 | AS44: =IF(COUNTBLANK(AD44:AR44)>0,"",SUM(AD44:AR44)) -> 8 | AT44: =IF(AS44="","",AS44/15*100) -> 53.333333 | AU44: Airtel Africa Governance Report FY2022/23 + Financial Statements FY2022/23 climate risk note 7.3 (cdn-webportal.airtelstream.net). Sustainability Committee meets monthly, Board updated quarterly; agenda explicitly names 'Pathway to net zero and reduction of GHG emissions: complexity of modelling scope 1/2 initiatives and modelling for scope 3'. FS Note 7.3 'Our consideration of climate-related risks' confirms TCFD governance process and that auditors evaluated climate scenario considerations. CAVEAT: no standalone Sustainability Report 2023 located this session (URL attempts failed) so no direct FY2023 GHG figures/targets found -- M-series scored 0 pending that primary source, likely an undercount given FY2022/2024 both report figures, flagged for re-check.
A45: =C45&"_"&G45 -> 9_2024 | B45: 44 | C45: ='Panel Data (Long Format)'!B45 -> 9 | D45: ='Panel Data (Long Format)'!C45 -> AIRTELAFRI | E45: ='Panel Data (Long Format)'!D45 -> Airtel Africa Plc | F45: ='Panel Data (Long Format)'!E45 -> ICT | G45: ='Panel Data (Long Format)'!F45 -> 2024 | H45: 1 | I45: 1 | J45: 1 | K45: 1 | L45: 0 | M45: 1 | N45: 1 | O45: 1 | P45: 0 | Q45: 1 | R45: 1 | S45: 1 | T45: 1 | U45: 1 | V45: 0 | W45: 1 | X45: 1 | Y45: 1 | Z45: 1 | AA45: 1 | AB45: =IF(COUNTBLANK(H45:AA45)>0,"",SUM(H45:AA45)) -> 17 | AC45: =IF(AB45="","",AB45/20*100) -> 85 | AD45: 1 | AE45: 1 | AF45: 0 | AG45: 1 | AH45: 1 | AI45: 1 | AJ45: 1 | AK45: 1 | AL45: 1 | AM45: 1 | AN45: 1 | AO45: 1 | AP45: 1 | AQ45: 1 | AR45: 0 | AS45: =IF(COUNTBLANK(AD45:AR45)>0,"",SUM(AD45:AR45)) -> 13 | AT45: =IF(AS45="","",AS45/15*100) -> 86.666667 | AU45: Airtel Africa Sustainability Report 2024 + Financial Statements 2024 (cdn-webportal.airtelstream.net). Report explicitly sections 'Transition risks / Physical risks' (CDQ S1=1); scenario analysis conducted 'in 2023/24' per retrospective FY2025 report text (S3/S5=1). Scope1=82,871; Scope2=45,632; Scope3=891,182 tCO2e (2023/24) reported with named methodology section. Remuneration Committee link to sustainability explicit. Board sustainability-champion director role not yet clearly confirmed for this year (G5=0).
A46: =C46&"_"&G46 -> 9_2025 | B46: 45 | C46: ='Panel Data (Long Format)'!B46 -> 9 | D46: ='Panel Data (Long Format)'!C46 -> AIRTELAFRI | E46: ='Panel Data (Long Format)'!D46 -> Airtel Africa Plc | F46: ='Panel Data (Long Format)'!E46 -> ICT | G46: ='Panel Data (Long Format)'!F46 -> 2025 | H46: 1 | I46: 1 | J46: 1 | K46: 1 | L46: 1 | M46: 1 | N46: 1 | O46: 1 | P46: 0 | Q46: 1 | R46: 1 | S46: 1 | T46: 1 | U46: 1 | V46: 0 | W46: 1 | X46: 1 | Y46: 1 | Z46: 1 | AA46: 1 | AB46: =IF(COUNTBLANK(H46:AA46)>0,"",SUM(H46:AA46)) -> 18 | AC46: =IF(AB46="","",AB46/20*100) -> 90 | AD46: 1 | AE46: 1 | AF46: 1 | AG46: 1 | AH46: 1 | AI46: 1 | AJ46: 1 | AK46: 1 | AL46: 1 | AM46: 1 | AN46: 1 | AO46: 1 | AP46: 1 | AQ46: 1 | AR46: 0 | AS46: =IF(COUNTBLANK(AD46:AR46)>0,"",SUM(AD46:AR46)) -> 14 | AT46: =IF(AS46="","",AS46/15*100) -> 93.333333 | AU46: Airtel Africa AR2025 digital-first HTML report -- Managing our risk (p021), Sustainability strategy (p023), Governance structures (p036), Audit&Risk Committee report (p041), TCFD disclosures (p025), New accounting pronouncements note (p066). Governance structures page names 5 Board committees incl. Sustainability Committee (chair: CEO Sunil Taldar; mgmt member 'Oladimeji Olaniyan, Head of strategy and sustainability') and 'Annika Poutiainen, Board member and sustainability champion' (G5=1). Full TCFD-structured disclosure: 3-scenario climate analysis (current-policy/high-temp/net-zero), both physical & transition risks tabulated, Scope1=89,869/Scope2=44,151/Scope3='n/a with reasoned 1-yr verification lag' tCO2e (M3=1 per reasoned-omission rule), target -62% carbon intensity by 2032 from 2022 baseline with -14% progress reported, ExCo LTIP/KRA explicitly linked to carbon reduction. Note 4 'New accounting pronouncements to be adopted' lists only an IAS 21 amendment -- no IFRS S1/S2/ISSB mention anywhere located across all AR2025 pages fetched, hence Adopter_Dummy blank despite substantive voluntary TCFD-aligned disclosure.
A47: =C47&"_"&G47 -> 10_2021 | B47: 46 | C47: ='Panel Data (Long Format)'!B47 -> 10 | D47: ='Panel Data (Long Format)'!C47 -> ALEX | E47: ='Panel Data (Long Format)'!D47 -> Aluminium Extrusion Industries Plc | F47: ='Panel Data (Long Format)'!E47 -> NATURAL RESOURCES | G47: ='Panel Data (Long Format)'!F47 -> 2021 | H47: 0 | I47: 0 | J47: 0 | K47: 0 | L47: 0 | M47: 0 | N47: 0 | O47: 0 | P47: 0 | Q47: 0 | R47: 0 | S47: 0 | T47: 0 | U47: 0 | V47: 0 | W47: 0 | X47: 0 | Y47: 0 | Z47: 0 | AA47: 0 | AB47: =IF(COUNTBLANK(H47:AA47)>0,"",SUM(H47:AA47)) -> 0 | AC47: =IF(AB47="","",AB47/20*100) -> 0 | AD47: 0 | AE47: 0 | AF47: 0 | AG47: 0 | AH47: 0 | AI47: 0 | AJ47: 0 | AK47: 0 | AL47: 0 | AM47: 0 | AN47: 0 | AO47: 0 | AP47: 0 | AQ47: 0 | AR47: 0 | AS47: =IF(COUNTBLANK(AD47:AR47)>0,"",SUM(AD47:AR47)) -> 0 | AT47: =IF(AS47="","",AS47/15*100) -> 0 | AU47: GAP-FILL: ALEX FY2021: primary source NOT accessible this session - the FY2022 NGX doclib filing (which would carry an FY2021 comparative) returned as an image-only/non-machine-readable PDF ('[This PDF is empty or contains no machine-readable text]'), and no readable FY2023/2024/2025 filing or company-website AFS could be located within this session's search budget (parent company is Tower Aluminium (Nigeria) Plc). Scored 0/20 SDQ, 0/15 CDQ, FLAGGED as unconfirmed/inaccessible-source, consistent with this dataset's THOMASWY/image-only-PDF precedent - a strong candidate for re-verification with OCR or an alternate source.
A48: =C48&"_"&G48 -> 10_2022 | B48: 47 | C48: ='Panel Data (Long Format)'!B48 -> 10 | D48: ='Panel Data (Long Format)'!C48 -> ALEX | E48: ='Panel Data (Long Format)'!D48 -> Aluminium Extrusion Industries Plc | F48: ='Panel Data (Long Format)'!E48 -> NATURAL RESOURCES | G48: ='Panel Data (Long Format)'!F48 -> 2022 | H48: 0 | I48: 0 | J48: 0 | K48: 0 | L48: 0 | M48: 0 | N48: 0 | O48: 0 | P48: 0 | Q48: 0 | R48: 0 | S48: 0 | T48: 0 | U48: 0 | V48: 0 | W48: 0 | X48: 0 | Y48: 0 | Z48: 0 | AA48: 0 | AB48: =IF(COUNTBLANK(H48:AA48)>0,"",SUM(H48:AA48)) -> 0 | AC48: =IF(AB48="","",AB48/20*100) -> 0 | AD48: 0 | AE48: 0 | AF48: 0 | AG48: 0 | AH48: 0 | AI48: 0 | AJ48: 0 | AK48: 0 | AL48: 0 | AM48: 0 | AN48: 0 | AO48: 0 | AP48: 0 | AQ48: 0 | AR48: 0 | AS48: =IF(COUNTBLANK(AD48:AR48)>0,"",SUM(AD48:AR48)) -> 0 | AT48: =IF(AS48="","",AS48/15*100) -> 0 | AU48: GAP-FILL: ALEX FY2022: primary source NOT accessible this session - the FY2022 NGX doclib filing (which would carry an FY2021 comparative) returned as an image-only/non-machine-readable PDF ('[This PDF is empty or contains no machine-readable text]'), and no readable FY2023/2024/2025 filing or company-website AFS could be located within this session's search budget (parent company is Tower Aluminium (Nigeria) Plc). Scored 0/20 SDQ, 0/15 CDQ, FLAGGED as unconfirmed/inaccessible-source, consistent with this dataset's THOMASWY/image-only-PDF precedent - a strong candidate for re-verification with OCR or an alternate source.
